Workbook
Name PERFORMANCETASKS: 'INPUT DATA'!#REF!
Name PT: 'INPUT DATA'!#REF!
Name QA: 'INPUT DATA'!#REF!
Name QUARTERLYASSESSMENT: 'INPUT DATA'!#REF!
Name SUBJECTS: '[1]INPUT DATA'!$A$1002:$A$1005
Name Transmu_Table: 'INPUT DATA'!#REF!
Name WRITTENWORKS: 'INPUT DATA'!#REF!
Name WW: 'INPUT DATA'!#REF!

Sheet INPUT DATA
A1: Input Data Sheet for SHS E-Class Record
C4: REGION | G4: VI | L4: DIVISION | O4: ILOILO CITY
B5: SCHOOL NAME | G5: PHINMA UNIVERSITY OF ILOILO | T5: SCHOOL ID | X5: 442568 | AD5: SCHOOL YEAR | AG5: 2026-2027
A7: LEARNERS' NAMES | F7: GRADE & SECTION: | Q7: TEACHER: | AC7: SUBJECT:
Q8: SEMESTER: | S8: 1ST | AC8: TRACK: | AE8: Academic Track (except Immersion)
A12: MALE
A13: 1
A14: 2
A15: 3
A16: 4
A17: 5
A18: 6
A19: 7
A20: 8
A21: 9
A22: 10
A23: 11
A24: 12
... A62: 50
A63: FEMALE
A64: 1
A65: 2
A66: 3
A67: 4
A68: 5
A69: 6
A70: 7
A71: 8
A72: 9
A73: 10
A74: 11
A75: 12
... A113: 50
XEW1048576: ngoyababrab

Sheet 1ST
A1: Senior High School Class Record
A3: (Pursuant to Deped Order 8 series of 2015)
C4: REGION | H4: ='INPUT DATA'!G4 | M4: DIVISION | P4: ='INPUT DATA'!O4
B5: SCHOOL NAME | H5: ='INPUT DATA'!G5 | U5: SCHOOL ID | Y5: ='INPUT DATA'!$X$5 | AE5: SCHOOL YEAR | AJ5: ='INPUT DATA'!AG5
A7: =IF('INPUT DATA'!S8="","",IF('INPUT DATA'!S8="1ST","FIRST QUARTER",IF('INPUT DATA'!S8="2ND","THIRD QUARTER"))) | G7: GRADE & SECTION: | L7: ='INPUT DATA'!K7 | R7: TEACHER: | T7: ='INPUT DATA'!S7 | AD7: SUBJECT: | AF7: ='INPUT DATA'!AE7
R8: SEMESTER: | T8: ='INPUT DATA'!S8 | AD8: TRACK: | AF8: ='INPUT DATA'!AE8
A9: LEARNERS' NAMES | G9: =IF('INPUT DATA'!AE8="","",INDEX('Helper(IMPORTANT!)'!$AR$2:$AR$5,MATCH(AF8,'Helper(IMPORTANT!)'!$AQ$2:$AQ$5,0))) | T9: =IF('INPUT DATA'!AE8="","",INDEX('Helper(IMPORTANT!)'!$AS$2:$AS$5,MATCH(AF8,'Helper(IMPORTANT!)'!$AQ$2:$AQ$5,0))) | AG9: =IF('INPUT DATA'!AE8="","",INDEX('Helper(IMPORTANT!)'!$AT$2:$AT$5,MATCH(AF8,'Helper(IMPORTANT!)'!$AQ$2:$AQ$5,0))) | AL9: Initial Grade | AM9: Quarterly Grade
G10: 1 | H10: 2 | I10: 3 | J10: 4 | K10: 5 | L10: 6 | M10: 7 | N10: 8 | O10: 9 | P10: 10 | Q10: Total | R10: PS | S10: WS | T10: 1 | U10: 2 | V10: 3 | W10: 4 | X10: 5 | Y10: 6 | Z10: 7 | AA10: 8 | AB10: 9 | AC10: 10 | AD10: Total | AE10: PS | AF10: WS | AG10: AT | AH10: QE | AI10: Total | AJ10: PS | AK10: WS
A11: HIGHEST POSSIBLE SCORE | G11: 130 | H11: 60 | Q11: =IF(COUNT($G11:$P11)=0,"",SUM($G11:$P11)) | R11: 100 | S11: =IF('INPUT DATA'!AE8="","",INDEX('Helper(IMPORTANT!)'!$AU$2:$AU$5,MATCH(AF8,'Helper(IMPORTANT!)'!$AQ$2:$AQ$5,0))) | T11: 30 | AD11: =IF(COUNT($T11:$AC11)=0,"",SUM($T11:$AC11)) | AE11: 100 | AF11: =IF('INPUT DATA'!AE8="","",INDEX('Helper(IMPORTANT!)'!$AV$2:$AV$5,MATCH(AF8,'Helper(IMPORTANT!)'!$AQ$2:$AQ$5,0))) | AG11: 50 | AH11: 50 | AI11: =SUM(AG11:AH11) | AJ11: 100 | AK11: =IF('INPUT DATA'!AE8="","",INDEX('Helper(IMPORTANT!)'!$AW$2:$AW$5,MATCH(AF8,'Helper(IMPORTANT!)'!$AQ$2:$AQ$5,0)))
A12: NAME | E12: ID Number
A13: 1 | B13: ='INPUT DATA'!B13 | Q13: =IF(COUNT($G13:$P13)=0,"",SUM($G13:$P13)) | R13: =IFERROR(IF(Q13="","",ROUND(Q13/$Q$11*100,2)),"") | S13: =IFERROR(IF(R13="","",ROUND(R13*$S$11,2)),"") | AD13: =IF(COUNT($T13:$AC13)=0,"",SUM($T13:$AC13)) | AE13: =IFERROR(IF(AD13="","",ROUND(AD13/$AD$11*100,2)),"") | AF13: =IFERROR(IF(AE13="","",ROUND(AE13*$AF$11,2)),"") | AI13: =SUM(AG13:AH13) | AJ13: =IFERROR(IF(AI13="","",ROUND(AI13/$AI$11*100,2)),"") | AK13: =IFERROR(IF(AJ13="","",ROUND(AJ13*$AK$11,2)),"") | AL13: =IFERROR(S13+AF13+AK13,"") | AM13: {=IF(AL13="","",_xlfn.IFS(AND(AL13>=99.5,AL13<=100),100,AND(AL13>=98.32,AL13<=99.49),99,AND(AL13>=97.14,AL13<=98.31),98,AND(AL13>=95.96,AL13<=97.13),97,AND(AL13>=94.78,AL13<=95.95),96,AND(AL13>=93.6,AL13<=94.77),95,AND(AL13>=92.42,AL13<=93.59),94,AND(AL13>=91.24,AL13<=92.41),93,AND(AL13>=90.06,AL13<=91.23),92,AND(AL13>=88.88,AL13<=90.05),91,AND(AL13>=87.7,AL13<=88.87),90,AND(AL13>=86.52,AL13<=87.69),89,AND(AL13>=85.34,AL13<=86.51),88,AND(AL13>=84.16,AL13<=85.33),87,AND(AL13>=82.98,AL13<=84.15),86,AND(AL13>=81.8,AL13<=82.97),85,AND(AL13>=80.62,AL13<=81.79),84,AND(AL13>=79.44,AL13<=80.61),83,AND(AL13>=78.26,AL13<=79.43),82,AND(AL13>=77.08,AL13<=78.25),81,AND(AL13>=75.9,AL13<=77.07),80,AND(AL13>=74.72,AL13<=75.89),79,AND(AL13>=73.54,AL13<=74.71),78,AND(AL13>=72.36,AL13<=73.53),77,AND(AL13>=71.18,AL13<=72.35),76,AND(AL13>=70,AL13<=71.17),75,AND(AL13>=65.34,AL13<=69.99),74,AND(AL13>=60.67,AL13<=65.33),73,AND(AL13>=56.01,AL13<=60.66),72,AND(AL13>=51.34,AL13<=56),71,AND(AL13>=46.67,AL13<=51.33),70,AND(AL13>=42.01,AL13<=46.66),69,AND(AL13>=37.34,AL13<=42),68,AND(AL13>=32.68,AL13<=37.33),67,AND(AL13>=28.01,AL13<=32.67),66,AND(AL13>=23.35,AL13<=28),65,AND(AL13>=18.68,AL13<=23.34),64,AND(AL13>=14.01,AL13<=18.67),63,AND(AL13>=9.35,AL13<=14),62,AND(AL13>=4.68,AL13<=9.34),61,AND(AL13>=0,AL13<=4.67),60,TRUE,""))}
A14: 2 | B14: ='INPUT DATA'!B14 | Q14: =IF(COUNT($G14:$P14)=0,"",SUM($G14:$P14)) | R14: =IFERROR(IF(Q14="","",ROUND(Q14/$Q$11*100,2)),"") | S14: =IFERROR(IF(R14="","",ROUND(R14*$S$11,2)),"") | AD14: =IF(COUNT($T14:$AC14)=0,"",SUM($T14:$AC14)) | AE14: =IFERROR(IF(AD14="","",ROUND(AD14/$AD$11*100,2)),"") | AF14: =IFERROR(IF(AE14="","",ROUND(AE14*$AF$11,2)),"") | AI14: =SUM(AG14:AH14) | AJ14: =IFERROR(IF(AI14="","",ROUND(AI14/$AI$11*100,2)),"") | AK14: =IFERROR(IF(AJ14="","",ROUND(AJ14*$AK$11,2)),"") | AL14: =IFERROR(S14+AF14+AK14,"") | AM14: {=IF(AL14="","",_xlfn.IFS(AND(AL14>=99.5,AL14<=100),100,AND(AL14>=98.32,AL14<=99.49),99,AND(AL14>=97.14,AL14<=98.31),98,AND(AL14>=95.96,AL14<=97.13),97,AND(AL14>=94.78,AL14<=95.95),96,AND(AL14>=93.6,AL14<=94.77),95,AND(AL14>=92.42,AL14<=93.59),94,AND(AL14>=91.24,AL14<=92.41),93,AND(AL14>=90.06,AL14<=91.23),92,AND(AL14>=88.88,AL14<=90.05),91,AND(AL14>=87.7,AL14<=88.87),90,AND(AL14>=86.52,AL14<=87.69),89,AND(AL14>=85.34,AL14<=86.51),88,AND(AL14>=84.16,AL14<=85.33),87,AND(AL14>=82.98,AL14<=84.15),86,AND(AL14>=81.8,AL14<=82.97),85,AND(AL14>=80.62,AL14<=81.79),84,AND(AL14>=79.44,AL14<=80.61),83,AND(AL14>=78.26,AL14<=79.43),82,AND(AL14>=77.08,AL14<=78.25),81,AND(AL14>=75.9,AL14<=77.07),80,AND(AL14>=74.72,AL14<=75.89),79,AND(AL14>=73.54,AL14<=74.71),78,AND(AL14>=72.36,AL14<=73.53),77,AND(AL14>=71.18,AL14<=72.35),76,AND(AL14>=70,AL14<=71.17),75,AND(AL14>=65.34,AL14<=69.99),74,AND(AL14>=60.67,AL14<=65.33),73,AND(AL14>=56.01,AL14<=60.66),72,AND(AL14>=51.34,AL14<=56),71,AND(AL14>=46.67,AL14<=51.33),70,AND(AL14>=42.01,AL14<=46.66),69,AND(AL14>=37.34,AL14<=42),68,AND(AL14>=32.68,AL14<=37.33),67,AND(AL14>=28.01,AL14<=32.67),66,AND(AL14>=23.35,AL14<=28),65,AND(AL14>=18.68,AL14<=23.34),64,AND(AL14>=14.01,AL14<=18.67),63,AND(AL14>=9.35,AL14<=14),62,AND(AL14>=4.68,AL14<=9.34),61,AND(AL14>=0,AL14<=4.67),60,TRUE,""))}
A15: 3 | B15: ='INPUT DATA'!B15 | Q15: =IF(COUNT($G15:$P15)=0,"",SUM($G15:$P15)) | R15: =IFERROR(IF(Q15="","",ROUND(Q15/$Q$11*100,2)),"") | S15: =IFERROR(IF(R15="","",ROUND(R15*$S$11,2)),"") | AD15: =IF(COUNT($T15:$AC15)=0,"",SUM($T15:$AC15)) | AE15: =IFERROR(IF(AD15="","",ROUND(AD15/$AD$11*100,2)),"") | AF15: =IFERROR(IF(AE15="","",ROUND(AE15*$AF$11,2)),"") | AI15: =SUM(AG15:AH15) | AJ15: =IFERROR(IF(AI15="","",ROUND(AI15/$AI$11*100,2)),"") | AK15: =IFERROR(IF(AJ15="","",ROUND(AJ15*$AK$11,2)),"") | AL15: =IFERROR(S15+AF15+AK15,"") | AM15: {=IF(AL15="","",_xlfn.IFS(AND(AL15>=99.5,AL15<=100),100,AND(AL15>=98.32,AL15<=99.49),99,AND(AL15>=97.14,AL15<=98.31),98,AND(AL15>=95.96,AL15<=97.13),97,AND(AL15>=94.78,AL15<=95.95),96,AND(AL15>=93.6,AL15<=94.77),95,AND(AL15>=92.42,AL15<=93.59),94,AND(AL15>=91.24,AL15<=92.41),93,AND(AL15>=90.06,AL15<=91.23),92,AND(AL15>=88.88,AL15<=90.05),91,AND(AL15>=87.7,AL15<=88.87),90,AND(AL15>=86.52,AL15<=87.69),89,AND(AL15>=85.34,AL15<=86.51),88,AND(AL15>=84.16,AL15<=85.33),87,AND(AL15>=82.98,AL15<=84.15),86,AND(AL15>=81.8,AL15<=82.97),85,AND(AL15>=80.62,AL15<=81.79),84,AND(AL15>=79.44,AL15<=80.61),83,AND(AL15>=78.26,AL15<=79.43),82,AND(AL15>=77.08,AL15<=78.25),81,AND(AL15>=75.9,AL15<=77.07),80,AND(AL15>=74.72,AL15<=75.89),79,AND(AL15>=73.54,AL15<=74.71),78,AND(AL15>=72.36,AL15<=73.53),77,AND(AL15>=71.18,AL15<=72.35),76,AND(AL15>=70,AL15<=71.17),75,AND(AL15>=65.34,AL15<=69.99),74,AND(AL15>=60.67,AL15<=65.33),73,AND(AL15>=56.01,AL15<=60.66),72,AND(AL15>=51.34,AL15<=56),71,AND(AL15>=46.67,AL15<=51.33),70,AND(AL15>=42.01,AL15<=46.66),69,AND(AL15>=37.34,AL15<=42),68,AND(AL15>=32.68,AL15<=37.33),67,AND(AL15>=28.01,AL15<=32.67),66,AND(AL15>=23.35,AL15<=28),65,AND(AL15>=18.68,AL15<=23.34),64,AND(AL15>=14.01,AL15<=18.67),63,AND(AL15>=9.35,AL15<=14),62,AND(AL15>=4.68,AL15<=9.34),61,AND(AL15>=0,AL15<=4.67),60,TRUE,""))}
A16: 4 | B16: ='INPUT DATA'!B16 | Q16: =IF(COUNT($G16:$P16)=0,"",SUM($G16:$P16)) | R16: =IFERROR(IF(Q16="","",ROUND(Q16/$Q$11*100,2)),"") | S16: =IFERROR(IF(R16="","",ROUND(R16*$S$11,2)),"") | AD16: =IF(COUNT($T16:$AC16)=0,"",SUM($T16:$AC16)) | AE16: =IFERROR(IF(AD16="","",ROUND(AD16/$AD$11*100,2)),"") | AF16: =IFERROR(IF(AE16="","",ROUND(AE16*$AF$11,2)),"") | AI16: =SUM(AG16:AH16) | AJ16: =IFERROR(IF(AI16="","",ROUND(AI16/$AI$11*100,2)),"") | AK16: =IFERROR(IF(AJ16="","",ROUND(AJ16*$AK$11,2)),"") | AL16: =IFERROR(S16+AF16+AK16,"") | AM16: {=IF(AL16="","",_xlfn.IFS(AND(AL16>=99.5,AL16<=100),100,AND(AL16>=98.32,AL16<=99.49),99,AND(AL16>=97.14,AL16<=98.31),98,AND(AL16>=95.96,AL16<=97.13),97,AND(AL16>=94.78,AL16<=95.95),96,AND(AL16>=93.6,AL16<=94.77),95,AND(AL16>=92.42,AL16<=93.59),94,AND(AL16>=91.24,AL16<=92.41),93,AND(AL16>=90.06,AL16<=91.23),92,AND(AL16>=88.88,AL16<=90.05),91,AND(AL16>=87.7,AL16<=88.87),90,AND(AL16>=86.52,AL16<=87.69),89,AND(AL16>=85.34,AL16<=86.51),88,AND(AL16>=84.16,AL16<=85.33),87,AND(AL16>=82.98,AL16<=84.15),86,AND(AL16>=81.8,AL16<=82.97),85,AND(AL16>=80.62,AL16<=81.79),84,AND(AL16>=79.44,AL16<=80.61),83,AND(AL16>=78.26,AL16<=79.43),82,AND(AL16>=77.08,AL16<=78.25),81,AND(AL16>=75.9,AL16<=77.07),80,AND(AL16>=74.72,AL16<=75.89),79,AND(AL16>=73.54,AL16<=74.71),78,AND(AL16>=72.36,AL16<=73.53),77,AND(AL16>=71.18,AL16<=72.35),76,AND(AL16>=70,AL16<=71.17),75,AND(AL16>=65.34,AL16<=69.99),74,AND(AL16>=60.67,AL16<=65.33),73,AND(AL16>=56.01,AL16<=60.66),72,AND(AL16>=51.34,AL16<=56),71,AND(AL16>=46.67,AL16<=51.33),70,AND(AL16>=42.01,AL16<=46.66),69,AND(AL16>=37.34,AL16<=42),68,AND(AL16>=32.68,AL16<=37.33),67,AND(AL16>=28.01,AL16<=32.67),66,AND(AL16>=23.35,AL16<=28),65,AND(AL16>=18.68,AL16<=23.34),64,AND(AL16>=14.01,AL16<=18.67),63,AND(AL16>=9.35,AL16<=14),62,AND(AL16>=4.68,AL16<=9.34),61,AND(AL16>=0,AL16<=4.67),60,TRUE,""))}
A17: 5 | B17: ='INPUT DATA'!B17 | Q17: =IF(COUNT($G17:$P17)=0,"",SUM($G17:$P17)) | R17: =IFERROR(IF(Q17="","",ROUND(Q17/$Q$11*100,2)),"") | S17: =IFERROR(IF(R17="","",ROUND(R17*$S$11,2)),"") | AD17: =IF(COUNT($T17:$AC17)=0,"",SUM($T17:$AC17)) | AE17: =IFERROR(IF(AD17="","",ROUND(AD17/$AD$11*100,2)),"") | AF17: =IFERROR(IF(AE17="","",ROUND(AE17*$AF$11,2)),"") | AI17: =SUM(AG17:AH17) | AJ17: =IFERROR(IF(AI17="","",ROUND(AI17/$AI$11*100,2)),"") | AK17: =IFERROR(IF(AJ17="","",ROUND(AJ17*$AK$11,2)),"") | AL17: =IFERROR(S17+AF17+AK17,"") | AM17: {=IF(AL17="","",_xlfn.IFS(AND(AL17>=99.5,AL17<=100),100,AND(AL17>=98.32,AL17<=99.49),99,AND(AL17>=97.14,AL17<=98.31),98,AND(AL17>=95.96,AL17<=97.13),97,AND(AL17>=94.78,AL17<=95.95),96,AND(AL17>=93.6,AL17<=94.77),95,AND(AL17>=92.42,AL17<=93.59),94,AND(AL17>=91.24,AL17<=92.41),93,AND(AL17>=90.06,AL17<=91.23),92,AND(AL17>=88.88,AL17<=90.05),91,AND(AL17>=87.7,AL17<=88.87),90,AND(AL17>=86.52,AL17<=87.69),89,AND(AL17>=85.34,AL17<=86.51),88,AND(AL17>=84.16,AL17<=85.33),87,AND(AL17>=82.98,AL17<=84.15),86,AND(AL17>=81.8,AL17<=82.97),85,AND(AL17>=80.62,AL17<=81.79),84,AND(AL17>=79.44,AL17<=80.61),83,AND(AL17>=78.26,AL17<=79.43),82,AND(AL17>=77.08,AL17<=78.25),81,AND(AL17>=75.9,AL17<=77.07),80,AND(AL17>=74.72,AL17<=75.89),79,AND(AL17>=73.54,AL17<=74.71),78,AND(AL17>=72.36,AL17<=73.53),77,AND(AL17>=71.18,AL17<=72.35),76,AND(AL17>=70,AL17<=71.17),75,AND(AL17>=65.34,AL17<=69.99),74,AND(AL17>=60.67,AL17<=65.33),73,AND(AL17>=56.01,AL17<=60.66),72,AND(AL17>=51.34,AL17<=56),71,AND(AL17>=46.67,AL17<=51.33),70,AND(AL17>=42.01,AL17<=46.66),69,AND(AL17>=37.34,AL17<=42),68,AND(AL17>=32.68,AL17<=37.33),67,AND(AL17>=28.01,AL17<=32.67),66,AND(AL17>=23.35,AL17<=28),65,AND(AL17>=18.68,AL17<=23.34),64,AND(AL17>=14.01,AL17<=18.67),63,AND(AL17>=9.35,AL17<=14),62,AND(AL17>=4.68,AL17<=9.34),61,AND(AL17>=0,AL17<=4.67),60,TRUE,""))}
A18: 6 | B18: ='INPUT DATA'!B18 | Q18: =IF(COUNT($G18:$P18)=0,"",SUM($G18:$P18)) | R18: =IFERROR(IF(Q18="","",ROUND(Q18/$Q$11*100,2)),"") | S18: =IFERROR(IF(R18="","",ROUND(R18*$S$11,2)),"") | AD18: =IF(COUNT($T18:$AC18)=0,"",SUM($T18:$AC18)) | AE18: =IFERROR(IF(AD18="","",ROUND(AD18/$AD$11*100,2)),"") | AF18: =IFERROR(IF(AE18="","",ROUND(AE18*$AF$11,2)),"") | AI18: =SUM(AG18:AH18) | AJ18: =IFERROR(IF(AI18="","",ROUND(AI18/$AI$11*100,2)),"") | AK18: =IFERROR(IF(AJ18="","",ROUND(AJ18*$AK$11,2)),"") | AL18: =IFERROR(S18+AF18+AK18,"") | AM18: {=IF(AL18="","",_xlfn.IFS(AND(AL18>=99.5,AL18<=100),100,AND(AL18>=98.32,AL18<=99.49),99,AND(AL18>=97.14,AL18<=98.31),98,AND(AL18>=95.96,AL18<=97.13),97,AND(AL18>=94.78,AL18<=95.95),96,AND(AL18>=93.6,AL18<=94.77),95,AND(AL18>=92.42,AL18<=93.59),94,AND(AL18>=91.24,AL18<=92.41),93,AND(AL18>=90.06,AL18<=91.23),92,AND(AL18>=88.88,AL18<=90.05),91,AND(AL18>=87.7,AL18<=88.87),90,AND(AL18>=86.52,AL18<=87.69),89,AND(AL18>=85.34,AL18<=86.51),88,AND(AL18>=84.16,AL18<=85.33),87,AND(AL18>=82.98,AL18<=84.15),86,AND(AL18>=81.8,AL18<=82.97),85,AND(AL18>=80.62,AL18<=81.79),84,AND(AL18>=79.44,AL18<=80.61),83,AND(AL18>=78.26,AL18<=79.43),82,AND(AL18>=77.08,AL18<=78.25),81,AND(AL18>=75.9,AL18<=77.07),80,AND(AL18>=74.72,AL18<=75.89),79,AND(AL18>=73.54,AL18<=74.71),78,AND(AL18>=72.36,AL18<=73.53),77,AND(AL18>=71.18,AL18<=72.35),76,AND(AL18>=70,AL18<=71.17),75,AND(AL18>=65.34,AL18<=69.99),74,AND(AL18>=60.67,AL18<=65.33),73,AND(AL18>=56.01,AL18<=60.66),72,AND(AL18>=51.34,AL18<=56),71,AND(AL18>=46.67,AL18<=51.33),70,AND(AL18>=42.01,AL18<=46.66),69,AND(AL18>=37.34,AL18<=42),68,AND(AL18>=32.68,AL18<=37.33),67,AND(AL18>=28.01,AL18<=32.67),66,AND(AL18>=23.35,AL18<=28),65,AND(AL18>=18.68,AL18<=23.34),64,AND(AL18>=14.01,AL18<=18.67),63,AND(AL18>=9.35,AL18<=14),62,AND(AL18>=4.68,AL18<=9.34),61,AND(AL18>=0,AL18<=4.67),60,TRUE,""))}
A19: 7 | B19: ='INPUT DATA'!B19 | Q19: =IF(COUNT($G19:$P19)=0,"",SUM($G19:$P19)) | R19: =IFERROR(IF(Q19="","",ROUND(Q19/$Q$11*100,2)),"") | S19: =IFERROR(IF(R19="","",ROUND(R19*$S$11,2)),"") | AD19: =IF(COUNT($T19:$AC19)=0,"",SUM($T19:$AC19)) | AE19: =IFERROR(IF(AD19="","",ROUND(AD19/$AD$11*100,2)),"") | AF19: =IFERROR(IF(AE19="","",ROUND(AE19*$AF$11,2)),"") | AI19: =SUM(AG19:AH19) | AJ19: =IFERROR(IF(AI19="","",ROUND(AI19/$AI$11*100,2)),"") | AK19: =IFERROR(IF(AJ19="","",ROUND(AJ19*$AK$11,2)),"") | AL19: =IFERROR(S19+AF19+AK19,"") | AM19: {=IF(AL19="","",_xlfn.IFS(AND(AL19>=99.5,AL19<=100),100,AND(AL19>=98.32,AL19<=99.49),99,AND(AL19>=97.14,AL19<=98.31),98,AND(AL19>=95.96,AL19<=97.13),97,AND(AL19>=94.78,AL19<=95.95),96,AND(AL19>=93.6,AL19<=94.77),95,AND(AL19>=92.42,AL19<=93.59),94,AND(AL19>=91.24,AL19<=92.41),93,AND(AL19>=90.06,AL19<=91.23),92,AND(AL19>=88.88,AL19<=90.05),91,AND(AL19>=87.7,AL19<=88.87),90,AND(AL19>=86.52,AL19<=87.69),89,AND(AL19>=85.34,AL19<=86.51),88,AND(AL19>=84.16,AL19<=85.33),87,AND(AL19>=82.98,AL19<=84.15),86,AND(AL19>=81.8,AL19<=82.97),85,AND(AL19>=80.62,AL19<=81.79),84,AND(AL19>=79.44,AL19<=80.61),83,AND(AL19>=78.26,AL19<=79.43),82,AND(AL19>=77.08,AL19<=78.25),81,AND(AL19>=75.9,AL19<=77.07),80,AND(AL19>=74.72,AL19<=75.89),79,AND(AL19>=73.54,AL19<=74.71),78,AND(AL19>=72.36,AL19<=73.53),77,AND(AL19>=71.18,AL19<=72.35),76,AND(AL19>=70,AL19<=71.17),75,AND(AL19>=65.34,AL19<=69.99),74,AND(AL19>=60.67,AL19<=65.33),73,AND(AL19>=56.01,AL19<=60.66),72,AND(AL19>=51.34,AL19<=56),71,AND(AL19>=46.67,AL19<=51.33),70,AND(AL19>=42.01,AL19<=46.66),69,AND(AL19>=37.34,AL19<=42),68,AND(AL19>=32.68,AL19<=37.33),67,AND(AL19>=28.01,AL19<=32.67),66,AND(AL19>=23.35,AL19<=28),65,AND(AL19>=18.68,AL19<=23.34),64,AND(AL19>=14.01,AL19<=18.67),63,AND(AL19>=9.35,AL19<=14),62,AND(AL19>=4.68,AL19<=9.34),61,AND(AL19>=0,AL19<=4.67),60,TRUE,""))}
A20: 8 | B20: ='INPUT DATA'!B20 | Q20: =IF(COUNT($G20:$P20)=0,"",SUM($G20:$P20)) | R20: =IFERROR(IF(Q20="","",ROUND(Q20/$Q$11*100,2)),"") | S20: =IFERROR(IF(R20="","",ROUND(R20*$S$11,2)),"") | AD20: =IF(COUNT($T20:$AC20)=0,"",SUM($T20:$AC20)) | AE20: =IFERROR(IF(AD20="","",ROUND(AD20/$AD$11*100,2)),"") | AF20: =IFERROR(IF(AE20="","",ROUND(AE20*$AF$11,2)),"") | AI20: =SUM(AG20:AH20) | AJ20: =IFERROR(IF(AI20="","",ROUND(AI20/$AI$11*100,2)),"") | AK20: =IFERROR(IF(AJ20="","",ROUND(AJ20*$AK$11,2)),"") | AL20: =IFERROR(S20+AF20+AK20,"") | AM20: {=IF(AL20="","",_xlfn.IFS(AND(AL20>=99.5,AL20<=100),100,AND(AL20>=98.32,AL20<=99.49),99,AND(AL20>=97.14,AL20<=98.31),98,AND(AL20>=95.96,AL20<=97.13),97,AND(AL20>=94.78,AL20<=95.95),96,AND(AL20>=93.6,AL20<=94.77),95,AND(AL20>=92.42,AL20<=93.59),94,AND(AL20>=91.24,AL20<=92.41),93,AND(AL20>=90.06,AL20<=91.23),92,AND(AL20>=88.88,AL20<=90.05),91,AND(AL20>=87.7,AL20<=88.87),90,AND(AL20>=86.52,AL20<=87.69),89,AND(AL20>=85.34,AL20<=86.51),88,AND(AL20>=84.16,AL20<=85.33),87,AND(AL20>=82.98,AL20<=84.15),86,AND(AL20>=81.8,AL20<=82.97),85,AND(AL20>=80.62,AL20<=81.79),84,AND(AL20>=79.44,AL20<=80.61),83,AND(AL20>=78.26,AL20<=79.43),82,AND(AL20>=77.08,AL20<=78.25),81,AND(AL20>=75.9,AL20<=77.07),80,AND(AL20>=74.72,AL20<=75.89),79,AND(AL20>=73.54,AL20<=74.71),78,AND(AL20>=72.36,AL20<=73.53),77,AND(AL20>=71.18,AL20<=72.35),76,AND(AL20>=70,AL20<=71.17),75,AND(AL20>=65.34,AL20<=69.99),74,AND(AL20>=60.67,AL20<=65.33),73,AND(AL20>=56.01,AL20<=60.66),72,AND(AL20>=51.34,AL20<=56),71,AND(AL20>=46.67,AL20<=51.33),70,AND(AL20>=42.01,AL20<=46.66),69,AND(AL20>=37.34,AL20<=42),68,AND(AL20>=32.68,AL20<=37.33),67,AND(AL20>=28.01,AL20<=32.67),66,AND(AL20>=23.35,AL20<=28),65,AND(AL20>=18.68,AL20<=23.34),64,AND(AL20>=14.01,AL20<=18.67),63,AND(AL20>=9.35,AL20<=14),62,AND(AL20>=4.68,AL20<=9.34),61,AND(AL20>=0,AL20<=4.67),60,TRUE,""))}
A21: 9 | B21: ='INPUT DATA'!B21 | Q21: =IF(COUNT($G21:$P21)=0,"",SUM($G21:$P21)) | R21: =IFERROR(IF(Q21="","",ROUND(Q21/$Q$11*100,2)),"") | S21: =IFERROR(IF(R21="","",ROUND(R21*$S$11,2)),"") | AD21: =IF(COUNT($T21:$AC21)=0,"",SUM($T21:$AC21)) | AE21: =IFERROR(IF(AD21="","",ROUND(AD21/$AD$11*100,2)),"") | AF21: =IFERROR(IF(AE21="","",ROUND(AE21*$AF$11,2)),"") | AI21: =SUM(AG21:AH21) | AJ21: =IFERROR(IF(AI21="","",ROUND(AI21/$AI$11*100,2)),"") | AK21: =IFERROR(IF(AJ21="","",ROUND(AJ21*$AK$11,2)),"") | AL21: =IFERROR(S21+AF21+AK21,"") | AM21: {=IF(AL21="","",_xlfn.IFS(AND(AL21>=99.5,AL21<=100),100,AND(AL21>=98.32,AL21<=99.49),99,AND(AL21>=97.14,AL21<=98.31),98,AND(AL21>=95.96,AL21<=97.13),97,AND(AL21>=94.78,AL21<=95.95),96,AND(AL21>=93.6,AL21<=94.77),95,AND(AL21>=92.42,AL21<=93.59),94,AND(AL21>=91.24,AL21<=92.41),93,AND(AL21>=90.06,AL21<=91.23),92,AND(AL21>=88.88,AL21<=90.05),91,AND(AL21>=87.7,AL21<=88.87),90,AND(AL21>=86.52,AL21<=87.69),89,AND(AL21>=85.34,AL21<=86.51),88,AND(AL21>=84.16,AL21<=85.33),87,AND(AL21>=82.98,AL21<=84.15),86,AND(AL21>=81.8,AL21<=82.97),85,AND(AL21>=80.62,AL21<=81.79),84,AND(AL21>=79.44,AL21<=80.61),83,AND(AL21>=78.26,AL21<=79.43),82,AND(AL21>=77.08,AL21<=78.25),81,AND(AL21>=75.9,AL21<=77.07),80,AND(AL21>=74.72,AL21<=75.89),79,AND(AL21>=73.54,AL21<=74.71),78,AND(AL21>=72.36,AL21<=73.53),77,AND(AL21>=71.18,AL21<=72.35),76,AND(AL21>=70,AL21<=71.17),75,AND(AL21>=65.34,AL21<=69.99),74,AND(AL21>=60.67,AL21<=65.33),73,AND(AL21>=56.01,AL21<=60.66),72,AND(AL21>=51.34,AL21<=56),71,AND(AL21>=46.67,AL21<=51.33),70,AND(AL21>=42.01,AL21<=46.66),69,AND(AL21>=37.34,AL21<=42),68,AND(AL21>=32.68,AL21<=37.33),67,AND(AL21>=28.01,AL21<=32.67),66,AND(AL21>=23.35,AL21<=28),65,AND(AL21>=18.68,AL21<=23.34),64,AND(AL21>=14.01,AL21<=18.67),63,AND(AL21>=9.35,AL21<=14),62,AND(AL21>=4.68,AL21<=9.34),61,AND(AL21>=0,AL21<=4.67),60,TRUE,""))}
A22: 10 | B22: ='INPUT DATA'!B22 | Q22: =IF(COUNT($G22:$P22)=0,"",SUM($G22:$P22)) | R22: =IFERROR(IF(Q22="","",ROUND(Q22/$Q$11*100,2)),"") | S22: =IFERROR(IF(R22="","",ROUND(R22*$S$11,2)),"") | AD22: =IF(COUNT($T22:$AC22)=0,"",SUM($T22:$AC22)) | AE22: =IFERROR(IF(AD22="","",ROUND(AD22/$AD$11*100,2)),"") | AF22: =IFERROR(IF(AE22="","",ROUND(AE22*$AF$11,2)),"") | AI22: =SUM(AG22:AH22) | AJ22: =IFERROR(IF(AI22="","",ROUND(AI22/$AI$11*100,2)),"") | AK22: =IFERROR(IF(AJ22="","",ROUND(AJ22*$AK$11,2)),"") | AL22: =IFERROR(S22+AF22+AK22,"") | AM22: {=IF(AL22="","",_xlfn.IFS(AND(AL22>=99.5,AL22<=100),100,AND(AL22>=98.32,AL22<=99.49),99,AND(AL22>=97.14,AL22<=98.31),98,AND(AL22>=95.96,AL22<=97.13),97,AND(AL22>=94.78,AL22<=95.95),96,AND(AL22>=93.6,AL22<=94.77),95,AND(AL22>=92.42,AL22<=93.59),94,AND(AL22>=91.24,AL22<=92.41),93,AND(AL22>=90.06,AL22<=91.23),92,AND(AL22>=88.88,AL22<=90.05),91,AND(AL22>=87.7,AL22<=88.87),90,AND(AL22>=86.52,AL22<=87.69),89,AND(AL22>=85.34,AL22<=86.51),88,AND(AL22>=84.16,AL22<=85.33),87,AND(AL22>=82.98,AL22<=84.15),86,AND(AL22>=81.8,AL22<=82.97),85,AND(AL22>=80.62,AL22<=81.79),84,AND(AL22>=79.44,AL22<=80.61),83,AND(AL22>=78.26,AL22<=79.43),82,AND(AL22>=77.08,AL22<=78.25),81,AND(AL22>=75.9,AL22<=77.07),80,AND(AL22>=74.72,AL22<=75.89),79,AND(AL22>=73.54,AL22<=74.71),78,AND(AL22>=72.36,AL22<=73.53),77,AND(AL22>=71.18,AL22<=72.35),76,AND(AL22>=70,AL22<=71.17),75,AND(AL22>=65.34,AL22<=69.99),74,AND(AL22>=60.67,AL22<=65.33),73,AND(AL22>=56.01,AL22<=60.66),72,AND(AL22>=51.34,AL22<=56),71,AND(AL22>=46.67,AL22<=51.33),70,AND(AL22>=42.01,AL22<=46.66),69,AND(AL22>=37.34,AL22<=42),68,AND(AL22>=32.68,AL22<=37.33),67,AND(AL22>=28.01,AL22<=32.67),66,AND(AL22>=23.35,AL22<=28),65,AND(AL22>=18.68,AL22<=23.34),64,AND(AL22>=14.01,AL22<=18.67),63,AND(AL22>=9.35,AL22<=14),62,AND(AL22>=4.68,AL22<=9.34),61,AND(AL22>=0,AL22<=4.67),60,TRUE,""))}
A23: 11 | B23: ='INPUT DATA'!B23 | Q23: =IF(COUNT($G23:$P23)=0,"",SUM($G23:$P23)) | R23: =IFERROR(IF(Q23="","",ROUND(Q23/$Q$11*100,2)),"") | S23: =IFERROR(IF(R23="","",ROUND(R23*$S$11,2)),"") | AD23: =IF(COUNT($T23:$AC23)=0,"",SUM($T23:$AC23)) | AE23: =IFERROR(IF(AD23="","",ROUND(AD23/$AD$11*100,2)),"") | AF23: =IFERROR(IF(AE23="","",ROUND(AE23*$AF$11,2)),"") | AI23: =SUM(AG23:AH23) | AJ23: =IFERROR(IF(AI23="","",ROUND(AI23/$AI$11*100,2)),"") | AK23: =IFERROR(IF(AJ23="","",ROUND(AJ23*$AK$11,2)),"") | AL23: =IFERROR(S23+AF23+AK23,"") | AM23: {=IF(AL23="","",_xlfn.IFS(AND(AL23>=99.5,AL23<=100),100,AND(AL23>=98.32,AL23<=99.49),99,AND(AL23>=97.14,AL23<=98.31),98,AND(AL23>=95.96,AL23<=97.13),97,AND(AL23>=94.78,AL23<=95.95),96,AND(AL23>=93.6,AL23<=94.77),95,AND(AL23>=92.42,AL23<=93.59),94,AND(AL23>=91.24,AL23<=92.41),93,AND(AL23>=90.06,AL23<=91.23),92,AND(AL23>=88.88,AL23<=90.05),91,AND(AL23>=87.7,AL23<=88.87),90,AND(AL23>=86.52,AL23<=87.69),89,AND(AL23>=85.34,AL23<=86.51),88,AND(AL23>=84.16,AL23<=85.33),87,AND(AL23>=82.98,AL23<=84.15),86,AND(AL23>=81.8,AL23<=82.97),85,AND(AL23>=80.62,AL23<=81.79),84,AND(AL23>=79.44,AL23<=80.61),83,AND(AL23>=78.26,AL23<=79.43),82,AND(AL23>=77.08,AL23<=78.25),81,AND(AL23>=75.9,AL23<=77.07),80,AND(AL23>=74.72,AL23<=75.89),79,AND(AL23>=73.54,AL23<=74.71),78,AND(AL23>=72.36,AL23<=73.53),77,AND(AL23>=71.18,AL23<=72.35),76,AND(AL23>=70,AL23<=71.17),75,AND(AL23>=65.34,AL23<=69.99),74,AND(AL23>=60.67,AL23<=65.33),73,AND(AL23>=56.01,AL23<=60.66),72,AND(AL23>=51.34,AL23<=56),71,AND(AL23>=46.67,AL23<=51.33),70,AND(AL23>=42.01,AL23<=46.66),69,AND(AL23>=37.34,AL23<=42),68,AND(AL23>=32.68,AL23<=37.33),67,AND(AL23>=28.01,AL23<=32.67),66,AND(AL23>=23.35,AL23<=28),65,AND(AL23>=18.68,AL23<=23.34),64,AND(AL23>=14.01,AL23<=18.67),63,AND(AL23>=9.35,AL23<=14),62,AND(AL23>=4.68,AL23<=9.34),61,AND(AL23>=0,AL23<=4.67),60,TRUE,""))}
A24: 12 | B24: ='INPUT DATA'!B24 | Q24: =IF(COUNT($G24:$P24)=0,"",SUM($G24:$P24)) | R24: =IFERROR(IF(Q24="","",ROUND(Q24/$Q$11*100,2)),"") | S24: =IFERROR(IF(R24="","",ROUND(R24*$S$11,2)),"") | AD24: =IF(COUNT($T24:$AC24)=0,"",SUM($T24:$AC24)) | AE24: =IFERROR(IF(AD24="","",ROUND(AD24/$AD$11*100,2)),"") | AF24: =IFERROR(IF(AE24="","",ROUND(AE24*$AF$11,2)),"") | AI24: =SUM(AG24:AH24) | AJ24: =IFERROR(IF(AI24="","",ROUND(AI24/$AI$11*100,2)),"") | AK24: =IFERROR(IF(AJ24="","",ROUND(AJ24*$AK$11,2)),"") | AL24: =IFERROR(S24+AF24+AK24,"") | AM24: {=IF(AL24="","",_xlfn.IFS(AND(AL24>=99.5,AL24<=100),100,AND(AL24>=98.32,AL24<=99.49),99,AND(AL24>=97.14,AL24<=98.31),98,AND(AL24>=95.96,AL24<=97.13),97,AND(AL24>=94.78,AL24<=95.95),96,AND(AL24>=93.6,AL24<=94.77),95,AND(AL24>=92.42,AL24<=93.59),94,AND(AL24>=91.24,AL24<=92.41),93,AND(AL24>=90.06,AL24<=91.23),92,AND(AL24>=88.88,AL24<=90.05),91,AND(AL24>=87.7,AL24<=88.87),90,AND(AL24>=86.52,AL24<=87.69),89,AND(AL24>=85.34,AL24<=86.51),88,AND(AL24>=84.16,AL24<=85.33),87,AND(AL24>=82.98,AL24<=84.15),86,AND(AL24>=81.8,AL24<=82.97),85,AND(AL24>=80.62,AL24<=81.79),84,AND(AL24>=79.44,AL24<=80.61),83,AND(AL24>=78.26,AL24<=79.43),82,AND(AL24>=77.08,AL24<=78.25),81,AND(AL24>=75.9,AL24<=77.07),80,AND(AL24>=74.72,AL24<=75.89),79,AND(AL24>=73.54,AL24<=74.71),78,AND(AL24>=72.36,AL24<=73.53),77,AND(AL24>=71.18,AL24<=72.35),76,AND(AL24>=70,AL24<=71.17),75,AND(AL24>=65.34,AL24<=69.99),74,AND(AL24>=60.67,AL24<=65.33),73,AND(AL24>=56.01,AL24<=60.66),72,AND(AL24>=51.34,AL24<=56),71,AND(AL24>=46.67,AL24<=51.33),70,AND(AL24>=42.01,AL24<=46.66),69,AND(AL24>=37.34,AL24<=42),68,AND(AL24>=32.68,AL24<=37.33),67,AND(AL24>=28.01,AL24<=32.67),66,AND(AL24>=23.35,AL24<=28),65,AND(AL24>=18.68,AL24<=23.34),64,AND(AL24>=14.01,AL24<=18.67),63,AND(AL24>=9.35,AL24<=14),62,AND(AL24>=4.68,AL24<=9.34),61,AND(AL24>=0,AL24<=4.67),60,TRUE,""))}
... A112: 49 | B112: ='INPUT DATA'!B112 | Q112: =IF(COUNT($G112:$P112)=0,"",SUM($G112:$P112)) | R112: =IFERROR(IF(Q112="","",ROUND(Q112/$Q$11*100,2)),"") | S112: =IFERROR(IF(R112="","",ROUND(R112*$S$11,2)),"") | AD112: =IF(COUNT($T112:$AC112)=0,"",SUM($T112:$AC112)) | AE112: =IFERROR(IF(AD112="","",ROUND(AD112/$AD$11*100,2)),"") | AF112: =IFERROR(IF(AE112="","",ROUND(AE112*$AF$11,2)),"") | AI112: =SUM(AG112:AH112) | AJ112: =IFERROR(IF(AI112="","",ROUND(AI112/$AI$11*100,2)),"") | AK112: =IFERROR(IF(AJ112="","",ROUND(AJ112*$AK$11,2)),"") | AL112: =IFERROR(S112+AF112+AK112,"") | AM112: {=IF(AL112="","",_xlfn.IFS(AND(AL112>=99.5,AL112<=100),100,AND(AL112>=98.32,AL112<=99.49),99,AND(AL112>=97.14,AL112<=98.31),98,AND(AL112>=95.96,AL112<=97.13),97,AND(AL112>=94.78,AL112<=95.95),96,AND(AL112>=93.6,AL112<=94.77),95,AND(AL112>=92.42,AL112<=93.59),94,AND(AL112>=91.24,AL112<=92.41),93,AND(AL112>=90.06,AL112<=91.23),92,AND(AL112>=88.88,AL112<=90.05),91,AND(AL112>=87.7,AL112<=88.87),90,AND(AL112>=86.52,AL112<=87.69),89,AND(AL112>=85.34,AL112<=86.51),88,AND(AL112>=84.16,AL112<=85.33),87,AND(AL112>=82.98,AL112<=84.15),86,AND(AL112>=81.8,AL112<=82.97),85,AND(AL112>=80.62,AL112<=81.79),84,AND(AL112>=79.44,AL112<=80.61),83,AND(AL112>=78.26,AL112<=79.43),82,AND(AL112>=77.08,AL112<=78.25),81,AND(AL112>=75.9,AL112<=77.07),80,AND(AL112>=74.72,AL112<=75.89),79,AND(AL112>=73.54,AL112<=74.71),78,AND(AL112>=72.36,AL112<=73.53),77,AND(AL112>=71.18,AL112<=72.35),76,AND(AL112>=70,AL112<=71.17),75,AND(AL112>=65.34,AL112<=69.99),74,AND(AL112>=60.67,AL112<=65.33),73,AND(AL112>=56.01,AL112<=60.66),72,AND(AL112>=51.34,AL112<=56),71,AND(AL112>=46.67,AL112<=51.33),70,AND(AL112>=42.01,AL112<=46.66),69,AND(AL112>=37.34,AL112<=42),68,AND(AL112>=32.68,AL112<=37.33),67,AND(AL112>=28.01,AL112<=32.67),66,AND(AL112>=23.35,AL112<=28),65,AND(AL112>=18.68,AL112<=23.34),64,AND(AL112>=14.01,AL112<=18.67),63,AND(AL112>=9.35,AL112<=14),62,AND(AL112>=4.68,AL112<=9.34),61,AND(AL112>=0,AL112<=4.67),60,TRUE,""))}
A113: 50 | B113: ='INPUT DATA'!B113 | E113: 21 | Q113: =IF(COUNT($G113:$P113)=0,"",SUM($G113:$P113)) | R113: =IFERROR(IF(Q113="","",ROUND(Q113/$Q$11*100,2)),"") | S113: =IFERROR(IF(R113="","",ROUND(R113*$S$11,2)),"") | AD113: =IF(COUNT($T113:$AC113)=0,"",SUM($T113:$AC113)) | AE113: =IFERROR(IF(AD113="","",ROUND(AD113/$AD$11*100,2)),"") | AF113: =IFERROR(IF(AE113="","",ROUND(AE113*$AF$11,2)),"") | AI113: =SUM(AG113:AH113) | AJ113: =IFERROR(IF(AI113="","",ROUND(AI113/$AI$11*100,2)),"") | AK113: =IFERROR(IF(AJ113="","",ROUND(AJ113*$AK$11,2)),"") | AL113: =IFERROR(S113+AF113+AK113,"") | AM113: {=IF(AL113="","",_xlfn.IFS(AND(AL113>=99.5,AL113<=100),100,AND(AL113>=98.32,AL113<=99.49),99,AND(AL113>=97.14,AL113<=98.31),98,AND(AL113>=95.96,AL113<=97.13),97,AND(AL113>=94.78,AL113<=95.95),96,AND(AL113>=93.6,AL113<=94.77),95,AND(AL113>=92.42,AL113<=93.59),94,AND(AL113>=91.24,AL113<=92.41),93,AND(AL113>=90.06,AL113<=91.23),92,AND(AL113>=88.88,AL113<=90.05),91,AND(AL113>=87.7,AL113<=88.87),90,AND(AL113>=86.52,AL113<=87.69),89,AND(AL113>=85.34,AL113<=86.51),88,AND(AL113>=84.16,AL113<=85.33),87,AND(AL113>=82.98,AL113<=84.15),86,AND(AL113>=81.8,AL113<=82.97),85,AND(AL113>=80.62,AL113<=81.79),84,AND(AL113>=79.44,AL113<=80.61),83,AND(AL113>=78.26,AL113<=79.43),82,AND(AL113>=77.08,AL113<=78.25),81,AND(AL113>=75.9,AL113<=77.07),80,AND(AL113>=74.72,AL113<=75.89),79,AND(AL113>=73.54,AL113<=74.71),78,AND(AL113>=72.36,AL113<=73.53),77,AND(AL113>=71.18,AL113<=72.35),76,AND(AL113>=70,AL113<=71.17),75,AND(AL113>=65.34,AL113<=69.99),74,AND(AL113>=60.67,AL113<=65.33),73,AND(AL113>=56.01,AL113<=60.66),72,AND(AL113>=51.34,AL113<=56),71,AND(AL113>=46.67,AL113<=51.33),70,AND(AL113>=42.01,AL113<=46.66),69,AND(AL113>=37.34,AL113<=42),68,AND(AL113>=32.68,AL113<=37.33),67,AND(AL113>=28.01,AL113<=32.67),66,AND(AL113>=23.35,AL113<=28),65,AND(AL113>=18.68,AL113<=23.34),64,AND(AL113>=14.01,AL113<=18.67),63,AND(AL113>=9.35,AL113<=14),62,AND(AL113>=4.68,AL113<=9.34),61,AND(AL113>=0,AL113<=4.67),60,TRUE,""))}
B116: Prepared by: | U116: Approved by:
B119: Subject Teacher | U119: SHS Principal

Sheet 2ND
A1: Senior High School Class Record
A3: (Pursuant to Deped Order 8 series of 2015)
C4: REGION | H4: ='INPUT DATA'!G4 | M4: DIVISION | P4: ='INPUT DATA'!O4
B5: SCHOOL NAME | H5: ='INPUT DATA'!G5 | U5: SCHOOL ID | Y5: ='INPUT DATA'!$X$5 | AE5: SCHOOL YEAR | AJ5: ='INPUT DATA'!AG5
A7: =IF('INPUT DATA'!S8="","",IF('INPUT DATA'!S8="1ST","SECOND QUARTER",IF('INPUT DATA'!S8="2ND","FOURTH QUARTER"))) | G7: GRADE & SECTION: | L7: ='INPUT DATA'!K7 | R7: TEACHER: | T7: ='INPUT DATA'!S7 | AD7: SUBJECT: | AF7: ='INPUT DATA'!AE7
R8: SEMESTER: | T8: ='INPUT DATA'!S8 | AD8: TRACK: | AF8: ='INPUT DATA'!AE8
A9: LEARNERS' NAMES | G9: =IF('INPUT DATA'!AE8="","",INDEX('Helper(IMPORTANT!)'!$AR$2:$AR$5,MATCH(AF8,'Helper(IMPORTANT!)'!$AQ$2:$AQ$5,0))) | T9: =IF('INPUT DATA'!AE8="","",INDEX('Helper(IMPORTANT!)'!$AS$2:$AS$5,MATCH(AF8,'Helper(IMPORTANT!)'!$AQ$2:$AQ$5,0))) | AG9: =IF('INPUT DATA'!AE8="","",INDEX('Helper(IMPORTANT!)'!$AT$2:$AT$5,MATCH(AF8,'Helper(IMPORTANT!)'!$AQ$2:$AQ$5,0))) | AL9: Initial Grade | AM9: Quarterly Grade
G10: 1 | H10: 2 | I10: 3 | J10: 4 | K10: 5 | L10: 6 | M10: 7 | N10: 8 | O10: 9 | P10: 10 | Q10: Total | R10: PS | S10: WS | T10: 1 | U10: 2 | V10: 3 | W10: 4 | X10: 5 | Y10: 6 | Z10: 7 | AA10: 8 | AB10: 9 | AC10: 10 | AD10: Total | AE10: PS | AF10: WS | AG10: AT | AH10: QE | AI10: Total | AJ10: PS | AK10: WS
A11: HIGHEST POSSIBLE SCORE | Q11: =IF(COUNT($G11:$P11)=0,"",SUM($G11:$P11)) | R11: 100 | S11: =IF('INPUT DATA'!AE8="","",INDEX('Helper(IMPORTANT!)'!$AU$2:$AU$5,MATCH(AF8,'Helper(IMPORTANT!)'!$AQ$2:$AQ$5,0))) | AD11: =IF(COUNT($T11:$AC11)=0,"",SUM($T11:$AC11)) | AE11: 100 | AF11: =IF('INPUT DATA'!AE8="","",INDEX('Helper(IMPORTANT!)'!$AV$2:$AV$5,MATCH(AF8,'Helper(IMPORTANT!)'!$AQ$2:$AQ$5,0))) | AG11: 50 | AH11: 50 | AI11: =SUM(AG11:AH11) | AJ11: 100 | AK11: =IF('INPUT DATA'!AE8="","",INDEX('Helper(IMPORTANT!)'!$AW$2:$AW$5,MATCH(AF8,'Helper(IMPORTANT!)'!$AQ$2:$AQ$5,0)))
A12: NAME | E12: ID Number
A13: 1 | B13: ='INPUT DATA'!B13 | E13: ='1ST'!E13 | Q13: =IF(COUNT($G13:$P13)=0,"",SUM($G13:$P13)) | R13: =IFERROR(IF(Q13="","",ROUND(Q13/$Q$11*100,2)),"") | S13: =IFERROR(IF(R13="","",ROUND(R13*$S$11,2)),"") | AD13: =IF(COUNT($T13:$AC13)=0,"",SUM($T13:$AC13)) | AE13: =IFERROR(IF(AD13="","",ROUND(AD13/$AD$11*100,2)),"") | AF13: =IFERROR(IF(AE13="","",ROUND(AE13*$AF$11,2)),"") | AI13: =SUM(AG13:AH13) | AJ13: =IFERROR(IF(AI13="","",ROUND(AI13/$AI$11*100,2)),"") | AK13: =IFERROR(IF(AJ13="","",ROUND(AJ13*$AK$11,2)),"") | AL13: =IFERROR(S13+AF13+AK13,"") | AM13: {=IF(AL13="","",_xlfn.IFS(AND(AL13>=99.5,AL13<=100),100,AND(AL13>=98.32,AL13<=99.49),99,AND(AL13>=97.14,AL13<=98.31),98,AND(AL13>=95.96,AL13<=97.13),97,AND(AL13>=94.78,AL13<=95.95),96,AND(AL13>=93.6,AL13<=94.77),95,AND(AL13>=92.42,AL13<=93.59),94,AND(AL13>=91.24,AL13<=92.41),93,AND(AL13>=90.06,AL13<=91.23),92,AND(AL13>=88.88,AL13<=90.05),91,AND(AL13>=87.7,AL13<=88.87),90,AND(AL13>=86.52,AL13<=87.69),89,AND(AL13>=85.34,AL13<=86.51),88,AND(AL13>=84.16,AL13<=85.33),87,AND(AL13>=82.98,AL13<=84.15),86,AND(AL13>=81.8,AL13<=82.97),85,AND(AL13>=80.62,AL13<=81.79),84,AND(AL13>=79.44,AL13<=80.61),83,AND(AL13>=78.26,AL13<=79.43),82,AND(AL13>=77.08,AL13<=78.25),81,AND(AL13>=75.9,AL13<=77.07),80,AND(AL13>=74.72,AL13<=75.89),79,AND(AL13>=73.54,AL13<=74.71),78,AND(AL13>=72.36,AL13<=73.53),77,AND(AL13>=71.18,AL13<=72.35),76,AND(AL13>=70,AL13<=71.17),75,AND(AL13>=65.34,AL13<=69.99),74,AND(AL13>=60.67,AL13<=65.33),73,AND(AL13>=56.01,AL13<=60.66),72,AND(AL13>=51.34,AL13<=56),71,AND(AL13>=46.67,AL13<=51.33),70,AND(AL13>=42.01,AL13<=46.66),69,AND(AL13>=37.34,AL13<=42),68,AND(AL13>=32.68,AL13<=37.33),67,AND(AL13>=28.01,AL13<=32.67),66,AND(AL13>=23.35,AL13<=28),65,AND(AL13>=18.68,AL13<=23.34),64,AND(AL13>=14.01,AL13<=18.67),63,AND(AL13>=9.35,AL13<=14),62,AND(AL13>=4.68,AL13<=9.34),61,AND(AL13>=0,AL13<=4.67),60,TRUE,""))}
A14: 2 | B14: ='INPUT DATA'!B14 | E14: ='1ST'!E14 | Q14: =IF(COUNT($G14:$P14)=0,"",SUM($G14:$P14)) | R14: =IFERROR(IF(Q14="","",ROUND(Q14/$Q$11*100,2)),"") | S14: =IFERROR(IF(R14="","",ROUND(R14*$S$11,2)),"") | AD14: =IF(COUNT($T14:$AC14)=0,"",SUM($T14:$AC14)) | AE14: =IFERROR(IF(AD14="","",ROUND(AD14/$AD$11*100,2)),"") | AF14: =IFERROR(IF(AE14="","",ROUND(AE14*$AF$11,2)),"") | AI14: =SUM(AG14:AH14) | AJ14: =IFERROR(IF(AI14="","",ROUND(AI14/$AI$11*100,2)),"") | AK14: =IFERROR(IF(AJ14="","",ROUND(AJ14*$AK$11,2)),"") | AL14: =IFERROR(S14+AF14+AK14,"") | AM14: {=IF(AL14="","",_xlfn.IFS(AND(AL14>=99.5,AL14<=100),100,AND(AL14>=98.32,AL14<=99.49),99,AND(AL14>=97.14,AL14<=98.31),98,AND(AL14>=95.96,AL14<=97.13),97,AND(AL14>=94.78,AL14<=95.95),96,AND(AL14>=93.6,AL14<=94.77),95,AND(AL14>=92.42,AL14<=93.59),94,AND(AL14>=91.24,AL14<=92.41),93,AND(AL14>=90.06,AL14<=91.23),92,AND(AL14>=88.88,AL14<=90.05),91,AND(AL14>=87.7,AL14<=88.87),90,AND(AL14>=86.52,AL14<=87.69),89,AND(AL14>=85.34,AL14<=86.51),88,AND(AL14>=84.16,AL14<=85.33),87,AND(AL14>=82.98,AL14<=84.15),86,AND(AL14>=81.8,AL14<=82.97),85,AND(AL14>=80.62,AL14<=81.79),84,AND(AL14>=79.44,AL14<=80.61),83,AND(AL14>=78.26,AL14<=79.43),82,AND(AL14>=77.08,AL14<=78.25),81,AND(AL14>=75.9,AL14<=77.07),80,AND(AL14>=74.72,AL14<=75.89),79,AND(AL14>=73.54,AL14<=74.71),78,AND(AL14>=72.36,AL14<=73.53),77,AND(AL14>=71.18,AL14<=72.35),76,AND(AL14>=70,AL14<=71.17),75,AND(AL14>=65.34,AL14<=69.99),74,AND(AL14>=60.67,AL14<=65.33),73,AND(AL14>=56.01,AL14<=60.66),72,AND(AL14>=51.34,AL14<=56),71,AND(AL14>=46.67,AL14<=51.33),70,AND(AL14>=42.01,AL14<=46.66),69,AND(AL14>=37.34,AL14<=42),68,AND(AL14>=32.68,AL14<=37.33),67,AND(AL14>=28.01,AL14<=32.67),66,AND(AL14>=23.35,AL14<=28),65,AND(AL14>=18.68,AL14<=23.34),64,AND(AL14>=14.01,AL14<=18.67),63,AND(AL14>=9.35,AL14<=14),62,AND(AL14>=4.68,AL14<=9.34),61,AND(AL14>=0,AL14<=4.67),60,TRUE,""))}
A15: 3 | B15: ='INPUT DATA'!B15 | E15: ='1ST'!E15 | Q15: =IF(COUNT($G15:$P15)=0,"",SUM($G15:$P15)) | R15: =IFERROR(IF(Q15="","",ROUND(Q15/$Q$11*100,2)),"") | S15: =IFERROR(IF(R15="","",ROUND(R15*$S$11,2)),"") | AD15: =IF(COUNT($T15:$AC15)=0,"",SUM($T15:$AC15)) | AE15: =IFERROR(IF(AD15="","",ROUND(AD15/$AD$11*100,2)),"") | AF15: =IFERROR(IF(AE15="","",ROUND(AE15*$AF$11,2)),"") | AI15: =SUM(AG15:AH15) | AJ15: =IFERROR(IF(AI15="","",ROUND(AI15/$AI$11*100,2)),"") | AK15: =IFERROR(IF(AJ15="","",ROUND(AJ15*$AK$11,2)),"") | AL15: =IFERROR(S15+AF15+AK15,"") | AM15: {=IF(AL15="","",_xlfn.IFS(AND(AL15>=99.5,AL15<=100),100,AND(AL15>=98.32,AL15<=99.49),99,AND(AL15>=97.14,AL15<=98.31),98,AND(AL15>=95.96,AL15<=97.13),97,AND(AL15>=94.78,AL15<=95.95),96,AND(AL15>=93.6,AL15<=94.77),95,AND(AL15>=92.42,AL15<=93.59),94,AND(AL15>=91.24,AL15<=92.41),93,AND(AL15>=90.06,AL15<=91.23),92,AND(AL15>=88.88,AL15<=90.05),91,AND(AL15>=87.7,AL15<=88.87),90,AND(AL15>=86.52,AL15<=87.69),89,AND(AL15>=85.34,AL15<=86.51),88,AND(AL15>=84.16,AL15<=85.33),87,AND(AL15>=82.98,AL15<=84.15),86,AND(AL15>=81.8,AL15<=82.97),85,AND(AL15>=80.62,AL15<=81.79),84,AND(AL15>=79.44,AL15<=80.61),83,AND(AL15>=78.26,AL15<=79.43),82,AND(AL15>=77.08,AL15<=78.25),81,AND(AL15>=75.9,AL15<=77.07),80,AND(AL15>=74.72,AL15<=75.89),79,AND(AL15>=73.54,AL15<=74.71),78,AND(AL15>=72.36,AL15<=73.53),77,AND(AL15>=71.18,AL15<=72.35),76,AND(AL15>=70,AL15<=71.17),75,AND(AL15>=65.34,AL15<=69.99),74,AND(AL15>=60.67,AL15<=65.33),73,AND(AL15>=56.01,AL15<=60.66),72,AND(AL15>=51.34,AL15<=56),71,AND(AL15>=46.67,AL15<=51.33),70,AND(AL15>=42.01,AL15<=46.66),69,AND(AL15>=37.34,AL15<=42),68,AND(AL15>=32.68,AL15<=37.33),67,AND(AL15>=28.01,AL15<=32.67),66,AND(AL15>=23.35,AL15<=28),65,AND(AL15>=18.68,AL15<=23.34),64,AND(AL15>=14.01,AL15<=18.67),63,AND(AL15>=9.35,AL15<=14),62,AND(AL15>=4.68,AL15<=9.34),61,AND(AL15>=0,AL15<=4.67),60,TRUE,""))}
A16: 4 | B16: ='INPUT DATA'!B16 | E16: ='1ST'!E16 | Q16: =IF(COUNT($G16:$P16)=0,"",SUM($G16:$P16)) | R16: =IFERROR(IF(Q16="","",ROUND(Q16/$Q$11*100,2)),"") | S16: =IFERROR(IF(R16="","",ROUND(R16*$S$11,2)),"") | AD16: =IF(COUNT($T16:$AC16)=0,"",SUM($T16:$AC16)) | AE16: =IFERROR(IF(AD16="","",ROUND(AD16/$AD$11*100,2)),"") | AF16: =IFERROR(IF(AE16="","",ROUND(AE16*$AF$11,2)),"") | AI16: =SUM(AG16:AH16) | AJ16: =IFERROR(IF(AI16="","",ROUND(AI16/$AI$11*100,2)),"") | AK16: =IFERROR(IF(AJ16="","",ROUND(AJ16*$AK$11,2)),"") | AL16: =IFERROR(S16+AF16+AK16,"") | AM16: {=IF(AL16="","",_xlfn.IFS(AND(AL16>=99.5,AL16<=100),100,AND(AL16>=98.32,AL16<=99.49),99,AND(AL16>=97.14,AL16<=98.31),98,AND(AL16>=95.96,AL16<=97.13),97,AND(AL16>=94.78,AL16<=95.95),96,AND(AL16>=93.6,AL16<=94.77),95,AND(AL16>=92.42,AL16<=93.59),94,AND(AL16>=91.24,AL16<=92.41),93,AND(AL16>=90.06,AL16<=91.23),92,AND(AL16>=88.88,AL16<=90.05),91,AND(AL16>=87.7,AL16<=88.87),90,AND(AL16>=86.52,AL16<=87.69),89,AND(AL16>=85.34,AL16<=86.51),88,AND(AL16>=84.16,AL16<=85.33),87,AND(AL16>=82.98,AL16<=84.15),86,AND(AL16>=81.8,AL16<=82.97),85,AND(AL16>=80.62,AL16<=81.79),84,AND(AL16>=79.44,AL16<=80.61),83,AND(AL16>=78.26,AL16<=79.43),82,AND(AL16>=77.08,AL16<=78.25),81,AND(AL16>=75.9,AL16<=77.07),80,AND(AL16>=74.72,AL16<=75.89),79,AND(AL16>=73.54,AL16<=74.71),78,AND(AL16>=72.36,AL16<=73.53),77,AND(AL16>=71.18,AL16<=72.35),76,AND(AL16>=70,AL16<=71.17),75,AND(AL16>=65.34,AL16<=69.99),74,AND(AL16>=60.67,AL16<=65.33),73,AND(AL16>=56.01,AL16<=60.66),72,AND(AL16>=51.34,AL16<=56),71,AND(AL16>=46.67,AL16<=51.33),70,AND(AL16>=42.01,AL16<=46.66),69,AND(AL16>=37.34,AL16<=42),68,AND(AL16>=32.68,AL16<=37.33),67,AND(AL16>=28.01,AL16<=32.67),66,AND(AL16>=23.35,AL16<=28),65,AND(AL16>=18.68,AL16<=23.34),64,AND(AL16>=14.01,AL16<=18.67),63,AND(AL16>=9.35,AL16<=14),62,AND(AL16>=4.68,AL16<=9.34),61,AND(AL16>=0,AL16<=4.67),60,TRUE,""))}
A17: 5 | B17: ='INPUT DATA'!B17 | E17: ='1ST'!E17 | Q17: =IF(COUNT($G17:$P17)=0,"",SUM($G17:$P17)) | R17: =IFERROR(IF(Q17="","",ROUND(Q17/$Q$11*100,2)),"") | S17: =IFERROR(IF(R17="","",ROUND(R17*$S$11,2)),"") | AD17: =IF(COUNT($T17:$AC17)=0,"",SUM($T17:$AC17)) | AE17: =IFERROR(IF(AD17="","",ROUND(AD17/$AD$11*100,2)),"") | AF17: =IFERROR(IF(AE17="","",ROUND(AE17*$AF$11,2)),"") | AI17: =SUM(AG17:AH17) | AJ17: =IFERROR(IF(AI17="","",ROUND(AI17/$AI$11*100,2)),"") | AK17: =IFERROR(IF(AJ17="","",ROUND(AJ17*$AK$11,2)),"") | AL17: =IFERROR(S17+AF17+AK17,"") | AM17: {=IF(AL17="","",_xlfn.IFS(AND(AL17>=99.5,AL17<=100),100,AND(AL17>=98.32,AL17<=99.49),99,AND(AL17>=97.14,AL17<=98.31),98,AND(AL17>=95.96,AL17<=97.13),97,AND(AL17>=94.78,AL17<=95.95),96,AND(AL17>=93.6,AL17<=94.77),95,AND(AL17>=92.42,AL17<=93.59),94,AND(AL17>=91.24,AL17<=92.41),93,AND(AL17>=90.06,AL17<=91.23),92,AND(AL17>=88.88,AL17<=90.05),91,AND(AL17>=87.7,AL17<=88.87),90,AND(AL17>=86.52,AL17<=87.69),89,AND(AL17>=85.34,AL17<=86.51),88,AND(AL17>=84.16,AL17<=85.33),87,AND(AL17>=82.98,AL17<=84.15),86,AND(AL17>=81.8,AL17<=82.97),85,AND(AL17>=80.62,AL17<=81.79),84,AND(AL17>=79.44,AL17<=80.61),83,AND(AL17>=78.26,AL17<=79.43),82,AND(AL17>=77.08,AL17<=78.25),81,AND(AL17>=75.9,AL17<=77.07),80,AND(AL17>=74.72,AL17<=75.89),79,AND(AL17>=73.54,AL17<=74.71),78,AND(AL17>=72.36,AL17<=73.53),77,AND(AL17>=71.18,AL17<=72.35),76,AND(AL17>=70,AL17<=71.17),75,AND(AL17>=65.34,AL17<=69.99),74,AND(AL17>=60.67,AL17<=65.33),73,AND(AL17>=56.01,AL17<=60.66),72,AND(AL17>=51.34,AL17<=56),71,AND(AL17>=46.67,AL17<=51.33),70,AND(AL17>=42.01,AL17<=46.66),69,AND(AL17>=37.34,AL17<=42),68,AND(AL17>=32.68,AL17<=37.33),67,AND(AL17>=28.01,AL17<=32.67),66,AND(AL17>=23.35,AL17<=28),65,AND(AL17>=18.68,AL17<=23.34),64,AND(AL17>=14.01,AL17<=18.67),63,AND(AL17>=9.35,AL17<=14),62,AND(AL17>=4.68,AL17<=9.34),61,AND(AL17>=0,AL17<=4.67),60,TRUE,""))}
A18: 6 | B18: ='INPUT DATA'!B18 | E18: ='1ST'!E18 | Q18: =IF(COUNT($G18:$P18)=0,"",SUM($G18:$P18)) | R18: =IFERROR(IF(Q18="","",ROUND(Q18/$Q$11*100,2)),"") | S18: =IFERROR(IF(R18="","",ROUND(R18*$S$11,2)),"") | AD18: =IF(COUNT($T18:$AC18)=0,"",SUM($T18:$AC18)) | AE18: =IFERROR(IF(AD18="","",ROUND(AD18/$AD$11*100,2)),"") | AF18: =IFERROR(IF(AE18="","",ROUND(AE18*$AF$11,2)),"") | AI18: =SUM(AG18:AH18) | AJ18: =IFERROR(IF(AI18="","",ROUND(AI18/$AI$11*100,2)),"") | AK18: =IFERROR(IF(AJ18="","",ROUND(AJ18*$AK$11,2)),"") | AL18: =IFERROR(S18+AF18+AK18,"") | AM18: {=IF(AL18="","",_xlfn.IFS(AND(AL18>=99.5,AL18<=100),100,AND(AL18>=98.32,AL18<=99.49),99,AND(AL18>=97.14,AL18<=98.31),98,AND(AL18>=95.96,AL18<=97.13),97,AND(AL18>=94.78,AL18<=95.95),96,AND(AL18>=93.6,AL18<=94.77),95,AND(AL18>=92.42,AL18<=93.59),94,AND(AL18>=91.24,AL18<=92.41),93,AND(AL18>=90.06,AL18<=91.23),92,AND(AL18>=88.88,AL18<=90.05),91,AND(AL18>=87.7,AL18<=88.87),90,AND(AL18>=86.52,AL18<=87.69),89,AND(AL18>=85.34,AL18<=86.51),88,AND(AL18>=84.16,AL18<=85.33),87,AND(AL18>=82.98,AL18<=84.15),86,AND(AL18>=81.8,AL18<=82.97),85,AND(AL18>=80.62,AL18<=81.79),84,AND(AL18>=79.44,AL18<=80.61),83,AND(AL18>=78.26,AL18<=79.43),82,AND(AL18>=77.08,AL18<=78.25),81,AND(AL18>=75.9,AL18<=77.07),80,AND(AL18>=74.72,AL18<=75.89),79,AND(AL18>=73.54,AL18<=74.71),78,AND(AL18>=72.36,AL18<=73.53),77,AND(AL18>=71.18,AL18<=72.35),76,AND(AL18>=70,AL18<=71.17),75,AND(AL18>=65.34,AL18<=69.99),74,AND(AL18>=60.67,AL18<=65.33),73,AND(AL18>=56.01,AL18<=60.66),72,AND(AL18>=51.34,AL18<=56),71,AND(AL18>=46.67,AL18<=51.33),70,AND(AL18>=42.01,AL18<=46.66),69,AND(AL18>=37.34,AL18<=42),68,AND(AL18>=32.68,AL18<=37.33),67,AND(AL18>=28.01,AL18<=32.67),66,AND(AL18>=23.35,AL18<=28),65,AND(AL18>=18.68,AL18<=23.34),64,AND(AL18>=14.01,AL18<=18.67),63,AND(AL18>=9.35,AL18<=14),62,AND(AL18>=4.68,AL18<=9.34),61,AND(AL18>=0,AL18<=4.67),60,TRUE,""))}
A19: 7 | B19: ='INPUT DATA'!B19 | E19: ='1ST'!E19 | Q19: =IF(COUNT($G19:$P19)=0,"",SUM($G19:$P19)) | R19: =IFERROR(IF(Q19="","",ROUND(Q19/$Q$11*100,2)),"") | S19: =IFERROR(IF(R19="","",ROUND(R19*$S$11,2)),"") | AD19: =IF(COUNT($T19:$AC19)=0,"",SUM($T19:$AC19)) | AE19: =IFERROR(IF(AD19="","",ROUND(AD19/$AD$11*100,2)),"") | AF19: =IFERROR(IF(AE19="","",ROUND(AE19*$AF$11,2)),"") | AI19: =SUM(AG19:AH19) | AJ19: =IFERROR(IF(AI19="","",ROUND(AI19/$AI$11*100,2)),"") | AK19: =IFERROR(IF(AJ19="","",ROUND(AJ19*$AK$11,2)),"") | AL19: =IFERROR(S19+AF19+AK19,"") | AM19: {=IF(AL19="","",_xlfn.IFS(AND(AL19>=99.5,AL19<=100),100,AND(AL19>=98.32,AL19<=99.49),99,AND(AL19>=97.14,AL19<=98.31),98,AND(AL19>=95.96,AL19<=97.13),97,AND(AL19>=94.78,AL19<=95.95),96,AND(AL19>=93.6,AL19<=94.77),95,AND(AL19>=92.42,AL19<=93.59),94,AND(AL19>=91.24,AL19<=92.41),93,AND(AL19>=90.06,AL19<=91.23),92,AND(AL19>=88.88,AL19<=90.05),91,AND(AL19>=87.7,AL19<=88.87),90,AND(AL19>=86.52,AL19<=87.69),89,AND(AL19>=85.34,AL19<=86.51),88,AND(AL19>=84.16,AL19<=85.33),87,AND(AL19>=82.98,AL19<=84.15),86,AND(AL19>=81.8,AL19<=82.97),85,AND(AL19>=80.62,AL19<=81.79),84,AND(AL19>=79.44,AL19<=80.61),83,AND(AL19>=78.26,AL19<=79.43),82,AND(AL19>=77.08,AL19<=78.25),81,AND(AL19>=75.9,AL19<=77.07),80,AND(AL19>=74.72,AL19<=75.89),79,AND(AL19>=73.54,AL19<=74.71),78,AND(AL19>=72.36,AL19<=73.53),77,AND(AL19>=71.18,AL19<=72.35),76,AND(AL19>=70,AL19<=71.17),75,AND(AL19>=65.34,AL19<=69.99),74,AND(AL19>=60.67,AL19<=65.33),73,AND(AL19>=56.01,AL19<=60.66),72,AND(AL19>=51.34,AL19<=56),71,AND(AL19>=46.67,AL19<=51.33),70,AND(AL19>=42.01,AL19<=46.66),69,AND(AL19>=37.34,AL19<=42),68,AND(AL19>=32.68,AL19<=37.33),67,AND(AL19>=28.01,AL19<=32.67),66,AND(AL19>=23.35,AL19<=28),65,AND(AL19>=18.68,AL19<=23.34),64,AND(AL19>=14.01,AL19<=18.67),63,AND(AL19>=9.35,AL19<=14),62,AND(AL19>=4.68,AL19<=9.34),61,AND(AL19>=0,AL19<=4.67),60,TRUE,""))}
A20: 8 | B20: ='INPUT DATA'!B20 | E20: ='1ST'!E20 | Q20: =IF(COUNT($G20:$P20)=0,"",SUM($G20:$P20)) | R20: =IFERROR(IF(Q20="","",ROUND(Q20/$Q$11*100,2)),"") | S20: =IFERROR(IF(R20="","",ROUND(R20*$S$11,2)),"") | AD20: =IF(COUNT($T20:$AC20)=0,"",SUM($T20:$AC20)) | AE20: =IFERROR(IF(AD20="","",ROUND(AD20/$AD$11*100,2)),"") | AF20: =IFERROR(IF(AE20="","",ROUND(AE20*$AF$11,2)),"") | AI20: =SUM(AG20:AH20) | AJ20: =IFERROR(IF(AI20="","",ROUND(AI20/$AI$11*100,2)),"") | AK20: =IFERROR(IF(AJ20="","",ROUND(AJ20*$AK$11,2)),"") | AL20: =IFERROR(S20+AF20+AK20,"") | AM20: {=IF(AL20="","",_xlfn.IFS(AND(AL20>=99.5,AL20<=100),100,AND(AL20>=98.32,AL20<=99.49),99,AND(AL20>=97.14,AL20<=98.31),98,AND(AL20>=95.96,AL20<=97.13),97,AND(AL20>=94.78,AL20<=95.95),96,AND(AL20>=93.6,AL20<=94.77),95,AND(AL20>=92.42,AL20<=93.59),94,AND(AL20>=91.24,AL20<=92.41),93,AND(AL20>=90.06,AL20<=91.23),92,AND(AL20>=88.88,AL20<=90.05),91,AND(AL20>=87.7,AL20<=88.87),90,AND(AL20>=86.52,AL20<=87.69),89,AND(AL20>=85.34,AL20<=86.51),88,AND(AL20>=84.16,AL20<=85.33),87,AND(AL20>=82.98,AL20<=84.15),86,AND(AL20>=81.8,AL20<=82.97),85,AND(AL20>=80.62,AL20<=81.79),84,AND(AL20>=79.44,AL20<=80.61),83,AND(AL20>=78.26,AL20<=79.43),82,AND(AL20>=77.08,AL20<=78.25),81,AND(AL20>=75.9,AL20<=77.07),80,AND(AL20>=74.72,AL20<=75.89),79,AND(AL20>=73.54,AL20<=74.71),78,AND(AL20>=72.36,AL20<=73.53),77,AND(AL20>=71.18,AL20<=72.35),76,AND(AL20>=70,AL20<=71.17),75,AND(AL20>=65.34,AL20<=69.99),74,AND(AL20>=60.67,AL20<=65.33),73,AND(AL20>=56.01,AL20<=60.66),72,AND(AL20>=51.34,AL20<=56),71,AND(AL20>=46.67,AL20<=51.33),70,AND(AL20>=42.01,AL20<=46.66),69,AND(AL20>=37.34,AL20<=42),68,AND(AL20>=32.68,AL20<=37.33),67,AND(AL20>=28.01,AL20<=32.67),66,AND(AL20>=23.35,AL20<=28),65,AND(AL20>=18.68,AL20<=23.34),64,AND(AL20>=14.01,AL20<=18.67),63,AND(AL20>=9.35,AL20<=14),62,AND(AL20>=4.68,AL20<=9.34),61,AND(AL20>=0,AL20<=4.67),60,TRUE,""))}
A21: 9 | B21: ='INPUT DATA'!B21 | E21: ='1ST'!E21 | Q21: =IF(COUNT($G21:$P21)=0,"",SUM($G21:$P21)) | R21: =IFERROR(IF(Q21="","",ROUND(Q21/$Q$11*100,2)),"") | S21: =IFERROR(IF(R21="","",ROUND(R21*$S$11,2)),"") | AD21: =IF(COUNT($T21:$AC21)=0,"",SUM($T21:$AC21)) | AE21: =IFERROR(IF(AD21="","",ROUND(AD21/$AD$11*100,2)),"") | AF21: =IFERROR(IF(AE21="","",ROUND(AE21*$AF$11,2)),"") | AI21: =SUM(AG21:AH21) | AJ21: =IFERROR(IF(AI21="","",ROUND(AI21/$AI$11*100,2)),"") | AK21: =IFERROR(IF(AJ21="","",ROUND(AJ21*$AK$11,2)),"") | AL21: =IFERROR(S21+AF21+AK21,"") | AM21: {=IF(AL21="","",_xlfn.IFS(AND(AL21>=99.5,AL21<=100),100,AND(AL21>=98.32,AL21<=99.49),99,AND(AL21>=97.14,AL21<=98.31),98,AND(AL21>=95.96,AL21<=97.13),97,AND(AL21>=94.78,AL21<=95.95),96,AND(AL21>=93.6,AL21<=94.77),95,AND(AL21>=92.42,AL21<=93.59),94,AND(AL21>=91.24,AL21<=92.41),93,AND(AL21>=90.06,AL21<=91.23),92,AND(AL21>=88.88,AL21<=90.05),91,AND(AL21>=87.7,AL21<=88.87),90,AND(AL21>=86.52,AL21<=87.69),89,AND(AL21>=85.34,AL21<=86.51),88,AND(AL21>=84.16,AL21<=85.33),87,AND(AL21>=82.98,AL21<=84.15),86,AND(AL21>=81.8,AL21<=82.97),85,AND(AL21>=80.62,AL21<=81.79),84,AND(AL21>=79.44,AL21<=80.61),83,AND(AL21>=78.26,AL21<=79.43),82,AND(AL21>=77.08,AL21<=78.25),81,AND(AL21>=75.9,AL21<=77.07),80,AND(AL21>=74.72,AL21<=75.89),79,AND(AL21>=73.54,AL21<=74.71),78,AND(AL21>=72.36,AL21<=73.53),77,AND(AL21>=71.18,AL21<=72.35),76,AND(AL21>=70,AL21<=71.17),75,AND(AL21>=65.34,AL21<=69.99),74,AND(AL21>=60.67,AL21<=65.33),73,AND(AL21>=56.01,AL21<=60.66),72,AND(AL21>=51.34,AL21<=56),71,AND(AL21>=46.67,AL21<=51.33),70,AND(AL21>=42.01,AL21<=46.66),69,AND(AL21>=37.34,AL21<=42),68,AND(AL21>=32.68,AL21<=37.33),67,AND(AL21>=28.01,AL21<=32.67),66,AND(AL21>=23.35,AL21<=28),65,AND(AL21>=18.68,AL21<=23.34),64,AND(AL21>=14.01,AL21<=18.67),63,AND(AL21>=9.35,AL21<=14),62,AND(AL21>=4.68,AL21<=9.34),61,AND(AL21>=0,AL21<=4.67),60,TRUE,""))}
A22: 10 | B22: ='INPUT DATA'!B22 | E22: ='1ST'!E22 | Q22: =IF(COUNT($G22:$P22)=0,"",SUM($G22:$P22)) | R22: =IFERROR(IF(Q22="","",ROUND(Q22/$Q$11*100,2)),"") | S22: =IFERROR(IF(R22="","",ROUND(R22*$S$11,2)),"") | AD22: =IF(COUNT($T22:$AC22)=0,"",SUM($T22:$AC22)) | AE22: =IFERROR(IF(AD22="","",ROUND(AD22/$AD$11*100,2)),"") | AF22: =IFERROR(IF(AE22="","",ROUND(AE22*$AF$11,2)),"") | AI22: =SUM(AG22:AH22) | AJ22: =IFERROR(IF(AI22="","",ROUND(AI22/$AI$11*100,2)),"") | AK22: =IFERROR(IF(AJ22="","",ROUND(AJ22*$AK$11,2)),"") | AL22: =IFERROR(S22+AF22+AK22,"") | AM22: {=IF(AL22="","",_xlfn.IFS(AND(AL22>=99.5,AL22<=100),100,AND(AL22>=98.32,AL22<=99.49),99,AND(AL22>=97.14,AL22<=98.31),98,AND(AL22>=95.96,AL22<=97.13),97,AND(AL22>=94.78,AL22<=95.95),96,AND(AL22>=93.6,AL22<=94.77),95,AND(AL22>=92.42,AL22<=93.59),94,AND(AL22>=91.24,AL22<=92.41),93,AND(AL22>=90.06,AL22<=91.23),92,AND(AL22>=88.88,AL22<=90.05),91,AND(AL22>=87.7,AL22<=88.87),90,AND(AL22>=86.52,AL22<=87.69),89,AND(AL22>=85.34,AL22<=86.51),88,AND(AL22>=84.16,AL22<=85.33),87,AND(AL22>=82.98,AL22<=84.15),86,AND(AL22>=81.8,AL22<=82.97),85,AND(AL22>=80.62,AL22<=81.79),84,AND(AL22>=79.44,AL22<=80.61),83,AND(AL22>=78.26,AL22<=79.43),82,AND(AL22>=77.08,AL22<=78.25),81,AND(AL22>=75.9,AL22<=77.07),80,AND(AL22>=74.72,AL22<=75.89),79,AND(AL22>=73.54,AL22<=74.71),78,AND(AL22>=72.36,AL22<=73.53),77,AND(AL22>=71.18,AL22<=72.35),76,AND(AL22>=70,AL22<=71.17),75,AND(AL22>=65.34,AL22<=69.99),74,AND(AL22>=60.67,AL22<=65.33),73,AND(AL22>=56.01,AL22<=60.66),72,AND(AL22>=51.34,AL22<=56),71,AND(AL22>=46.67,AL22<=51.33),70,AND(AL22>=42.01,AL22<=46.66),69,AND(AL22>=37.34,AL22<=42),68,AND(AL22>=32.68,AL22<=37.33),67,AND(AL22>=28.01,AL22<=32.67),66,AND(AL22>=23.35,AL22<=28),65,AND(AL22>=18.68,AL22<=23.34),64,AND(AL22>=14.01,AL22<=18.67),63,AND(AL22>=9.35,AL22<=14),62,AND(AL22>=4.68,AL22<=9.34),61,AND(AL22>=0,AL22<=4.67),60,TRUE,""))}
A23: 11 | B23: ='INPUT DATA'!B23 | E23: ='1ST'!E23 | Q23: =IF(COUNT($G23:$P23)=0,"",SUM($G23:$P23)) | R23: =IFERROR(IF(Q23="","",ROUND(Q23/$Q$11*100,2)),"") | S23: =IFERROR(IF(R23="","",ROUND(R23*$S$11,2)),"") | AD23: =IF(COUNT($T23:$AC23)=0,"",SUM($T23:$AC23)) | AE23: =IFERROR(IF(AD23="","",ROUND(AD23/$AD$11*100,2)),"") | AF23: =IFERROR(IF(AE23="","",ROUND(AE23*$AF$11,2)),"") | AI23: =SUM(AG23:AH23) | AJ23: =IFERROR(IF(AI23="","",ROUND(AI23/$AI$11*100,2)),"") | AK23: =IFERROR(IF(AJ23="","",ROUND(AJ23*$AK$11,2)),"") | AL23: =IFERROR(S23+AF23+AK23,"") | AM23: {=IF(AL23="","",_xlfn.IFS(AND(AL23>=99.5,AL23<=100),100,AND(AL23>=98.32,AL23<=99.49),99,AND(AL23>=97.14,AL23<=98.31),98,AND(AL23>=95.96,AL23<=97.13),97,AND(AL23>=94.78,AL23<=95.95),96,AND(AL23>=93.6,AL23<=94.77),95,AND(AL23>=92.42,AL23<=93.59),94,AND(AL23>=91.24,AL23<=92.41),93,AND(AL23>=90.06,AL23<=91.23),92,AND(AL23>=88.88,AL23<=90.05),91,AND(AL23>=87.7,AL23<=88.87),90,AND(AL23>=86.52,AL23<=87.69),89,AND(AL23>=85.34,AL23<=86.51),88,AND(AL23>=84.16,AL23<=85.33),87,AND(AL23>=82.98,AL23<=84.15),86,AND(AL23>=81.8,AL23<=82.97),85,AND(AL23>=80.62,AL23<=81.79),84,AND(AL23>=79.44,AL23<=80.61),83,AND(AL23>=78.26,AL23<=79.43),82,AND(AL23>=77.08,AL23<=78.25),81,AND(AL23>=75.9,AL23<=77.07),80,AND(AL23>=74.72,AL23<=75.89),79,AND(AL23>=73.54,AL23<=74.71),78,AND(AL23>=72.36,AL23<=73.53),77,AND(AL23>=71.18,AL23<=72.35),76,AND(AL23>=70,AL23<=71.17),75,AND(AL23>=65.34,AL23<=69.99),74,AND(AL23>=60.67,AL23<=65.33),73,AND(AL23>=56.01,AL23<=60.66),72,AND(AL23>=51.34,AL23<=56),71,AND(AL23>=46.67,AL23<=51.33),70,AND(AL23>=42.01,AL23<=46.66),69,AND(AL23>=37.34,AL23<=42),68,AND(AL23>=32.68,AL23<=37.33),67,AND(AL23>=28.01,AL23<=32.67),66,AND(AL23>=23.35,AL23<=28),65,AND(AL23>=18.68,AL23<=23.34),64,AND(AL23>=14.01,AL23<=18.67),63,AND(AL23>=9.35,AL23<=14),62,AND(AL23>=4.68,AL23<=9.34),61,AND(AL23>=0,AL23<=4.67),60,TRUE,""))}
A24: 12 | B24: ='INPUT DATA'!B24 | E24: ='1ST'!E24 | Q24: =IF(COUNT($G24:$P24)=0,"",SUM($G24:$P24)) | R24: =IFERROR(IF(Q24="","",ROUND(Q24/$Q$11*100,2)),"") | S24: =IFERROR(IF(R24="","",ROUND(R24*$S$11,2)),"") | AD24: =IF(COUNT($T24:$AC24)=0,"",SUM($T24:$AC24)) | AE24: =IFERROR(IF(AD24="","",ROUND(AD24/$AD$11*100,2)),"") | AF24: =IFERROR(IF(AE24="","",ROUND(AE24*$AF$11,2)),"") | AI24: =SUM(AG24:AH24) | AJ24: =IFERROR(IF(AI24="","",ROUND(AI24/$AI$11*100,2)),"") | AK24: =IFERROR(IF(AJ24="","",ROUND(AJ24*$AK$11,2)),"") | AL24: =IFERROR(S24+AF24+AK24,"") | AM24: {=IF(AL24="","",_xlfn.IFS(AND(AL24>=99.5,AL24<=100),100,AND(AL24>=98.32,AL24<=99.49),99,AND(AL24>=97.14,AL24<=98.31),98,AND(AL24>=95.96,AL24<=97.13),97,AND(AL24>=94.78,AL24<=95.95),96,AND(AL24>=93.6,AL24<=94.77),95,AND(AL24>=92.42,AL24<=93.59),94,AND(AL24>=91.24,AL24<=92.41),93,AND(AL24>=90.06,AL24<=91.23),92,AND(AL24>=88.88,AL24<=90.05),91,AND(AL24>=87.7,AL24<=88.87),90,AND(AL24>=86.52,AL24<=87.69),89,AND(AL24>=85.34,AL24<=86.51),88,AND(AL24>=84.16,AL24<=85.33),87,AND(AL24>=82.98,AL24<=84.15),86,AND(AL24>=81.8,AL24<=82.97),85,AND(AL24>=80.62,AL24<=81.79),84,AND(AL24>=79.44,AL24<=80.61),83,AND(AL24>=78.26,AL24<=79.43),82,AND(AL24>=77.08,AL24<=78.25),81,AND(AL24>=75.9,AL24<=77.07),80,AND(AL24>=74.72,AL24<=75.89),79,AND(AL24>=73.54,AL24<=74.71),78,AND(AL24>=72.36,AL24<=73.53),77,AND(AL24>=71.18,AL24<=72.35),76,AND(AL24>=70,AL24<=71.17),75,AND(AL24>=65.34,AL24<=69.99),74,AND(AL24>=60.67,AL24<=65.33),73,AND(AL24>=56.01,AL24<=60.66),72,AND(AL24>=51.34,AL24<=56),71,AND(AL24>=46.67,AL24<=51.33),70,AND(AL24>=42.01,AL24<=46.66),69,AND(AL24>=37.34,AL24<=42),68,AND(AL24>=32.68,AL24<=37.33),67,AND(AL24>=28.01,AL24<=32.67),66,AND(AL24>=23.35,AL24<=28),65,AND(AL24>=18.68,AL24<=23.34),64,AND(AL24>=14.01,AL24<=18.67),63,AND(AL24>=9.35,AL24<=14),62,AND(AL24>=4.68,AL24<=9.34),61,AND(AL24>=0,AL24<=4.67),60,TRUE,""))}
... A113: 50 | B113: ='INPUT DATA'!B113 | E113: ='1ST'!E113 | Q113: =IF(COUNT($G113:$P113)=0,"",SUM($G113:$P113)) | R113: =IFERROR(IF(Q113="","",ROUND(Q113/$Q$11*100,2)),"") | S113: =IFERROR(IF(R113="","",ROUND(R113*$S$11,2)),"") | AD113: =IF(COUNT($T113:$AC113)=0,"",SUM($T113:$AC113)) | AE113: =IFERROR(IF(AD113="","",ROUND(AD113/$AD$11*100,2)),"") | AF113: =IFERROR(IF(AE113="","",ROUND(AE113*$AF$11,2)),"") | AI113: =SUM(AG113:AH113) | AJ113: =IFERROR(IF(AI113="","",ROUND(AI113/$AI$11*100,2)),"") | AK113: =IFERROR(IF(AJ113="","",ROUND(AJ113*$AK$11,2)),"") | AL113: =IFERROR(S113+AF113+AK113,"") | AM113: {=IF(AL113="","",_xlfn.IFS(AND(AL113>=99.5,AL113<=100),100,AND(AL113>=98.32,AL113<=99.49),99,AND(AL113>=97.14,AL113<=98.31),98,AND(AL113>=95.96,AL113<=97.13),97,AND(AL113>=94.78,AL113<=95.95),96,AND(AL113>=93.6,AL113<=94.77),95,AND(AL113>=92.42,AL113<=93.59),94,AND(AL113>=91.24,AL113<=92.41),93,AND(AL113>=90.06,AL113<=91.23),92,AND(AL113>=88.88,AL113<=90.05),91,AND(AL113>=87.7,AL113<=88.87),90,AND(AL113>=86.52,AL113<=87.69),89,AND(AL113>=85.34,AL113<=86.51),88,AND(AL113>=84.16,AL113<=85.33),87,AND(AL113>=82.98,AL113<=84.15),86,AND(AL113>=81.8,AL113<=82.97),85,AND(AL113>=80.62,AL113<=81.79),84,AND(AL113>=79.44,AL113<=80.61),83,AND(AL113>=78.26,AL113<=79.43),82,AND(AL113>=77.08,AL113<=78.25),81,AND(AL113>=75.9,AL113<=77.07),80,AND(AL113>=74.72,AL113<=75.89),79,AND(AL113>=73.54,AL113<=74.71),78,AND(AL113>=72.36,AL113<=73.53),77,AND(AL113>=71.18,AL113<=72.35),76,AND(AL113>=70,AL113<=71.17),75,AND(AL113>=65.34,AL113<=69.99),74,AND(AL113>=60.67,AL113<=65.33),73,AND(AL113>=56.01,AL113<=60.66),72,AND(AL113>=51.34,AL113<=56),71,AND(AL113>=46.67,AL113<=51.33),70,AND(AL113>=42.01,AL113<=46.66),69,AND(AL113>=37.34,AL113<=42),68,AND(AL113>=32.68,AL113<=37.33),67,AND(AL113>=28.01,AL113<=32.67),66,AND(AL113>=23.35,AL113<=28),65,AND(AL113>=18.68,AL113<=23.34),64,AND(AL113>=14.01,AL113<=18.67),63,AND(AL113>=9.35,AL113<=14),62,AND(AL113>=4.68,AL113<=9.34),61,AND(AL113>=0,AL113<=4.67),60,TRUE,""))}
B116: Prepared by: | V116: Approved by:
B119: Subject Teacher | V119: SHS Principal

Sheet Final Semestral Grade
A1: Final Semestral Grades
C5: REGION | G5: ='INPUT DATA'!G4 | L5: DIVISION | O5: ='INPUT DATA'!O4 | S5: SCHOOL ID | W5: ='INPUT DATA'!X5
B6: SCHOOL NAME | G6: ='INPUT DATA'!G5 | S6: SCHOOL YEAR | W6: ='INPUT DATA'!AG5
A8: LEARNERS' NAMES | F8: GRADE & SECTION: | K8: ='INPUT DATA'!K7 | S8: SEMESTER: | V8: ='INPUT DATA'!S8
S9: SUBJECT: | V9: ='INPUT DATA'!AE7
F10: TEACHER: | I10: ='INPUT DATA'!S7 | S10: TRACK: | V10: ='INPUT DATA'!AE8
F11: =IF('INPUT DATA'!S8="","",IF('INPUT DATA'!S8="1ST","FIRST QUARTER",IF('INPUT DATA'!S8="2ND","THIRD QUARTER"))) | N11: =IF('INPUT DATA'!S8="","",IF('INPUT DATA'!S8="1ST","SECOND QUARTER",IF('INPUT DATA'!S8="2ND","FOURTH QUARTER"))) | V11: =IF('INPUT DATA'!S8="","",IF('INPUT DATA'!S8="1ST","FIRST SEMESTER FINAL GRADES",IF('INPUT DATA'!S8="2ND","SECOND SEMESTER FINAL GRADES"))) | Z11: REMARK
A12: MALE
A13: 1 | B13: ='INPUT DATA'!B13 | F13: ='1ST'!AM13 | N13: ='2ND'!AM13 | V13: =IF(OR(F13="",N13=""),"",IF(ISERROR(ROUND(AVERAGE(F13,N13),0)),"",ROUND(AVERAGE(F13,N13),0))) | Z13: =IF(OR($F13="",N13="",$V13=""),"",IF($V13>=75,"PASSED","FAILED"))
A14: 2 | B14: ='INPUT DATA'!B14 | F14: ='1ST'!AM14 | N14: ='2ND'!AM14 | V14: =IF(OR(F14="",N14=""),"",IF(ISERROR(ROUND(AVERAGE(F14,N14),0)),"",ROUND(AVERAGE(F14,N14),0))) | Z14: =IF(OR($F14="",N14="",$V14=""),"",IF($V14>=75,"PASSED","FAILED"))
A15: 3 | B15: ='INPUT DATA'!B15 | F15: ='1ST'!AM15 | N15: ='2ND'!AM15 | V15: =IF(OR(F15="",N15=""),"",IF(ISERROR(ROUND(AVERAGE(F15,N15),0)),"",ROUND(AVERAGE(F15,N15),0))) | Z15: =IF(OR($F15="",N15="",$V15=""),"",IF($V15>=75,"PASSED","FAILED"))
A16: 4 | B16: ='INPUT DATA'!B16 | F16: ='1ST'!AM16 | N16: ='2ND'!AM16 | V16: =IF(OR(F16="",N16=""),"",IF(ISERROR(ROUND(AVERAGE(F16,N16),0)),"",ROUND(AVERAGE(F16,N16),0))) | Z16: =IF(OR($F16="",N16="",$V16=""),"",IF($V16>=75,"PASSED","FAILED"))
A17: 5 | B17: ='INPUT DATA'!B17 | F17: ='1ST'!AM17 | N17: ='2ND'!AM17 | V17: =IF(OR(F17="",N17=""),"",IF(ISERROR(ROUND(AVERAGE(F17,N17),0)),"",ROUND(AVERAGE(F17,N17),0))) | Z17: =IF(OR($F17="",N17="",$V17=""),"",IF($V17>=75,"PASSED","FAILED"))
A18: 6 | B18: ='INPUT DATA'!B18 | F18: ='1ST'!AM18 | N18: ='2ND'!AM18 | V18: =IF(OR(F18="",N18=""),"",IF(ISERROR(ROUND(AVERAGE(F18,N18),0)),"",ROUND(AVERAGE(F18,N18),0))) | Z18: =IF(OR($F18="",N18="",$V18=""),"",IF($V18>=75,"PASSED","FAILED"))
A19: 7 | B19: ='INPUT DATA'!B19 | F19: ='1ST'!AM19 | N19: ='2ND'!AM19 | V19: =IF(OR(F19="",N19=""),"",IF(ISERROR(ROUND(AVERAGE(F19,N19),0)),"",ROUND(AVERAGE(F19,N19),0))) | Z19: =IF(OR($F19="",N19="",$V19=""),"",IF($V19>=75,"PASSED","FAILED"))
A20: 8 | B20: ='INPUT DATA'!B20 | F20: ='1ST'!AM20 | N20: ='2ND'!AM20 | V20: =IF(OR(F20="",N20=""),"",IF(ISERROR(ROUND(AVERAGE(F20,N20),0)),"",ROUND(AVERAGE(F20,N20),0))) | Z20: =IF(OR($F20="",N20="",$V20=""),"",IF($V20>=75,"PASSED","FAILED"))
A21: 9 | B21: ='INPUT DATA'!B21 | F21: ='1ST'!AM21 | N21: ='2ND'!AM21 | V21: =IF(OR(F21="",N21=""),"",IF(ISERROR(ROUND(AVERAGE(F21,N21),0)),"",ROUND(AVERAGE(F21,N21),0))) | Z21: =IF(OR($F21="",N21="",$V21=""),"",IF($V21>=75,"PASSED","FAILED"))
A22: 10 | B22: ='INPUT DATA'!B22 | F22: ='1ST'!AM22 | N22: ='2ND'!AM22 | V22: =IF(OR(F22="",N22=""),"",IF(ISERROR(ROUND(AVERAGE(F22,N22),0)),"",ROUND(AVERAGE(F22,N22),0))) | Z22: =IF(OR($F22="",N22="",$V22=""),"",IF($V22>=75,"PASSED","FAILED"))
A23: 11 | B23: ='INPUT DATA'!B23 | F23: ='1ST'!AM23 | N23: ='2ND'!AM23 | V23: =IF(OR(F23="",N23=""),"",IF(ISERROR(ROUND(AVERAGE(F23,N23),0)),"",ROUND(AVERAGE(F23,N23),0))) | Z23: =IF(OR($F23="",N23="",$V23=""),"",IF($V23>=75,"PASSED","FAILED"))
A24: 12 | B24: ='INPUT DATA'!B24 | F24: ='1ST'!AM24 | N24: ='2ND'!AM24 | V24: =IF(OR(F24="",N24=""),"",IF(ISERROR(ROUND(AVERAGE(F24,N24),0)),"",ROUND(AVERAGE(F24,N24),0))) | Z24: =IF(OR($F24="",N24="",$V24=""),"",IF($V24>=75,"PASSED","FAILED"))
